[2025-02-18T11:21:11.580+0000] {local_task_job_runner.py:123} INFO - ::group::Pre task execution logs
[2025-02-18T11:21:11.598+0000] {taskinstance.py:2614} INFO - Dependencies all met for dep_context=non-requeueable deps ti=<TaskInstance: google_news_scraper.save_article_data manual__2025-02-18T11:20:36.681685+00:00 [queued]>
[2025-02-18T11:21:11.606+0000] {taskinstance.py:2614} INFO - Dependencies all met for dep_context=requeueable deps ti=<TaskInstance: google_news_scraper.save_article_data manual__2025-02-18T11:20:36.681685+00:00 [queued]>
[2025-02-18T11:21:11.607+0000] {taskinstance.py:2867} INFO - Starting attempt 1 of 3
[2025-02-18T11:21:11.621+0000] {taskinstance.py:2890} INFO - Executing <Task(PythonOperator): save_article_data> on 2025-02-18 11:20:36.681685+00:00
[2025-02-18T11:21:11.630+0000] {warnings.py:112} WARNING - /home/***/.local/lib/python3.12/site-packages/***/task/task_runner/standard_task_runner.py:70: DeprecationWarning: This process (pid=1886) is multi-threaded, use of fork() may lead to deadlocks in the child.
  pid = os.fork()

[2025-02-18T11:21:11.632+0000] {standard_task_runner.py:104} INFO - Running: ['***', 'tasks', 'run', 'google_news_scraper', 'save_article_data', 'manual__2025-02-18T11:20:36.681685+00:00', '--job-id', '85', '--raw', '--subdir', 'DAGS_FOLDER/dag2.py', '--cfg-path', '/tmp/tmpd5_vdiwq']
[2025-02-18T11:21:11.634+0000] {standard_task_runner.py:105} INFO - Job 85: Subtask save_article_data
[2025-02-18T11:21:11.634+0000] {standard_task_runner.py:72} INFO - Started process 1900 to run task
[2025-02-18T11:21:11.679+0000] {task_command.py:467} INFO - Running <TaskInstance: google_news_scraper.save_article_data manual__2025-02-18T11:20:36.681685+00:00 [running]> on host 9546a27fb76d
[2025-02-18T11:21:11.760+0000] {taskinstance.py:3134} INFO - Exporting env vars: AIRFLOW_CTX_DAG_OWNER='***' AIRFLOW_CTX_DAG_ID='google_news_scraper' AIRFLOW_CTX_TASK_ID='save_article_data' AIRFLOW_CTX_EXECUTION_DATE='2025-02-18T11:20:36.681685+00:00' AIRFLOW_CTX_TRY_NUMBER='1' AIRFLOW_CTX_DAG_RUN_ID='manual__2025-02-18T11:20:36.681685+00:00'
[2025-02-18T11:21:11.762+0000] {logging_mixin.py:190} INFO - Task instance is in running state
[2025-02-18T11:21:11.763+0000] {logging_mixin.py:190} INFO -  Previous state of the Task instance: queued
[2025-02-18T11:21:11.764+0000] {logging_mixin.py:190} INFO - Current task name:save_article_data state:running start_date:2025-02-18 11:21:11.599462+00:00
[2025-02-18T11:21:11.764+0000] {logging_mixin.py:190} INFO - Dag name:google_news_scraper and current dag run status:running
[2025-02-18T11:21:11.765+0000] {taskinstance.py:732} INFO - ::endgroup::
[2025-02-18T11:21:11.782+0000] {taskinstance.py:3313} ERROR - Task failed with exception
Traceback (most recent call last):
  File "/home/airflow/.local/lib/python3.12/site-packages/airflow/models/taskinstance.py", line 768, in _execute_task
    result = _execute_callable(context=context, **execute_callable_kwargs)
             ^^^^^^^^^^^^^^^^^^^^^^^^^^^^^^^^^^^^^^^^^^^^^^^^^^^^^^^^^^^^^
  File "/home/airflow/.local/lib/python3.12/site-packages/airflow/models/taskinstance.py", line 734, in _execute_callable
    return ExecutionCallableRunner(
           ^^^^^^^^^^^^^^^^^^^^^^^^
  File "/home/airflow/.local/lib/python3.12/site-packages/airflow/utils/operator_helpers.py", line 252, in run
    return self.func(*args, **kwargs)
           ^^^^^^^^^^^^^^^^^^^^^^^^^^
  File "/home/airflow/.local/lib/python3.12/site-packages/airflow/models/baseoperator.py", line 424, in wrapper
    return func(self, *args, **kwargs)
           ^^^^^^^^^^^^^^^^^^^^^^^^^^^
  File "/home/airflow/.local/lib/python3.12/site-packages/airflow/operators/python.py", line 238, in execute
    return_value = self.execute_callable()
                   ^^^^^^^^^^^^^^^^^^^^^^^
  File "/home/airflow/.local/lib/python3.12/site-packages/airflow/operators/python.py", line 256, in execute_callable
    return runner.run(*self.op_args, **self.op_kwargs)
           ^^^^^^^^^^^^^^^^^^^^^^^^^^^^^^^^^^^^^^^^^^^
  File "/home/airflow/.local/lib/python3.12/site-packages/airflow/utils/operator_helpers.py", line 252, in run
    return self.func(*args, **kwargs)
           ^^^^^^^^^^^^^^^^^^^^^^^^^^
  File "/opt/airflow/dags/dag2.py", line 46, in save_article_data
    save_articles(articles, output_file_path)
  File "/opt/airflow/dags/google_news_scraper.py", line 298, in save_articles
    with open(output_file, 'w', encoding='utf-8') as file:
         ^^^^^^^^^^^^^^^^^^^^^^^^^^^^^^^^^^^^^^^^
FileNotFoundError: [Errno 2] No such file or directory: '/opt/airflow/C:/Users/Preethi/Downloads/assgn4/airflow-docker/dags/news_articles.json'
[2025-02-18T11:21:11.811+0000] {logging_mixin.py:190} INFO - Task instance in failure state
[2025-02-18T11:21:11.812+0000] {logging_mixin.py:190} INFO - Task start:2025-02-18 11:21:11.599462+00:00 end:2025-02-18 11:21:11.810954+00:00 duration:0.211492
[2025-02-18T11:21:11.813+0000] {logging_mixin.py:190} INFO - Task:<Task(PythonOperator): save_article_data> dag:<DAG: google_news_scraper> dagrun:<DagRun google_news_scraper @ 2025-02-18 11:20:36.681685+00:00: manual__2025-02-18T11:20:36.681685+00:00, state:running, queued_at: 2025-02-18 11:20:36.694914+00:00. externally triggered: True>
[2025-02-18T11:21:11.814+0000] {logging_mixin.py:190} INFO - Failure caused by [Errno 2] No such file or directory: '/opt/***/C:/Users/Preethi/Downloads/assgn4/***-docker/dags/news_articles.json'
[2025-02-18T11:21:11.815+0000] {taskinstance.py:1226} INFO - Marking task as UP_FOR_RETRY. dag_id=google_news_scraper, task_id=save_article_data, run_id=manual__2025-02-18T11:20:36.681685+00:00, execution_date=20250218T112036, start_date=20250218T112111, end_date=20250218T112111
[2025-02-18T11:21:11.843+0000] {taskinstance.py:341} INFO - ::group::Post task execution logs
[2025-02-18T11:21:11.844+0000] {standard_task_runner.py:124} ERROR - Failed to execute job 85 for task save_article_data ([Errno 2] No such file or directory: '/opt/airflow/C:/Users/Preethi/Downloads/assgn4/airflow-docker/dags/news_articles.json'; 1900)
Traceback (most recent call last):
  File "/home/airflow/.local/lib/python3.12/site-packages/airflow/task/task_runner/standard_task_runner.py", line 117, in _start_by_fork
    ret = args.func(args, dag=self.dag)
          ^^^^^^^^^^^^^^^^^^^^^^^^^^^^^
  File "/home/airflow/.local/lib/python3.12/site-packages/airflow/cli/cli_config.py", line 49, in command
    return func(*args, **kwargs)
           ^^^^^^^^^^^^^^^^^^^^^
  File "/home/airflow/.local/lib/python3.12/site-packages/airflow/utils/cli.py", line 116, in wrapper
    return f(*args, **kwargs)
           ^^^^^^^^^^^^^^^^^^
  File "/home/airflow/.local/lib/python3.12/site-packages/airflow/cli/commands/task_command.py", line 483, in task_run
    task_return_code = _run_task_by_selected_method(args, _dag, ti)
                       ^^^^^^^^^^^^^^^^^^^^^^^^^^^^^^^^^^^^^^^^^^^^
  File "/home/airflow/.local/lib/python3.12/site-packages/airflow/cli/commands/task_command.py", line 256, in _run_task_by_selected_method
    return _run_raw_task(args, ti)
           ^^^^^^^^^^^^^^^^^^^^^^^
  File "/home/airflow/.local/lib/python3.12/site-packages/airflow/cli/commands/task_command.py", line 341, in _run_raw_task
    return ti._run_raw_task(
           ^^^^^^^^^^^^^^^^^
  File "/home/airflow/.local/lib/python3.12/site-packages/airflow/utils/session.py", line 97, in wrapper
    return func(*args, session=session, **kwargs)
           ^^^^^^^^^^^^^^^^^^^^^^^^^^^^^^^^^^^^^^
  File "/home/airflow/.local/lib/python3.12/site-packages/airflow/models/taskinstance.py", line 3006, in _run_raw_task
    return _run_raw_task(
           ^^^^^^^^^^^^^^
  File "/home/airflow/.local/lib/python3.12/site-packages/airflow/models/taskinstance.py", line 274, in _run_raw_task
    TaskInstance._execute_task_with_callbacks(
  File "/home/airflow/.local/lib/python3.12/site-packages/airflow/models/taskinstance.py", line 3161, in _execute_task_with_callbacks
    result = self._execute_task(context, task_orig)
             ^^^^^^^^^^^^^^^^^^^^^^^^^^^^^^^^^^^^^^
  File "/home/airflow/.local/lib/python3.12/site-packages/airflow/models/taskinstance.py", line 3185, in _execute_task
    return _execute_task(self, context, task_orig)
           ^^^^^^^^^^^^^^^^^^^^^^^^^^^^^^^^^^^^^^^
  File "/home/airflow/.local/lib/python3.12/site-packages/airflow/models/taskinstance.py", line 768, in _execute_task
    result = _execute_callable(context=context, **execute_callable_kwargs)
             ^^^^^^^^^^^^^^^^^^^^^^^^^^^^^^^^^^^^^^^^^^^^^^^^^^^^^^^^^^^^^
  File "/home/airflow/.local/lib/python3.12/site-packages/airflow/models/taskinstance.py", line 734, in _execute_callable
    return ExecutionCallableRunner(
           ^^^^^^^^^^^^^^^^^^^^^^^^
  File "/home/airflow/.local/lib/python3.12/site-packages/airflow/utils/operator_helpers.py", line 252, in run
    return self.func(*args, **kwargs)
           ^^^^^^^^^^^^^^^^^^^^^^^^^^
  File "/home/airflow/.local/lib/python3.12/site-packages/airflow/models/baseoperator.py", line 424, in wrapper
    return func(self, *args, **kwargs)
           ^^^^^^^^^^^^^^^^^^^^^^^^^^^
  File "/home/airflow/.local/lib/python3.12/site-packages/airflow/operators/python.py", line 238, in execute
    return_value = self.execute_callable()
                   ^^^^^^^^^^^^^^^^^^^^^^^
  File "/home/airflow/.local/lib/python3.12/site-packages/airflow/operators/python.py", line 256, in execute_callable
    return runner.run(*self.op_args, **self.op_kwargs)
           ^^^^^^^^^^^^^^^^^^^^^^^^^^^^^^^^^^^^^^^^^^^
  File "/home/airflow/.local/lib/python3.12/site-packages/airflow/utils/operator_helpers.py", line 252, in run
    return self.func(*args, **kwargs)
           ^^^^^^^^^^^^^^^^^^^^^^^^^^
  File "/opt/airflow/dags/dag2.py", line 46, in save_article_data
    save_articles(articles, output_file_path)
  File "/opt/airflow/dags/google_news_scraper.py", line 298, in save_articles
    with open(output_file, 'w', encoding='utf-8') as file:
         ^^^^^^^^^^^^^^^^^^^^^^^^^^^^^^^^^^^^^^^^
FileNotFoundError: [Errno 2] No such file or directory: '/opt/airflow/C:/Users/Preethi/Downloads/assgn4/airflow-docker/dags/news_articles.json'
[2025-02-18T11:21:11.896+0000] {local_task_job_runner.py:266} INFO - Task exited with return code 1
[2025-02-18T11:21:11.920+0000] {taskinstance.py:3901} INFO - 0 downstream tasks scheduled from follow-on schedule check
[2025-02-18T11:21:11.924+0000] {local_task_job_runner.py:245} INFO - ::endgroup::
