[2025-02-16T17:39:35.347+0000] {local_task_job_runner.py:123} INFO - ::group::Pre task execution logs
[2025-02-16T17:39:35.363+0000] {taskinstance.py:2614} INFO - Dependencies all met for dep_context=non-requeueable deps ti=<TaskInstance: google_news_scraper.load_config manual__2025-02-16T17:25:22.072157+00:00 [queued]>
[2025-02-16T17:39:35.370+0000] {taskinstance.py:2614} INFO - Dependencies all met for dep_context=requeueable deps ti=<TaskInstance: google_news_scraper.load_config manual__2025-02-16T17:25:22.072157+00:00 [queued]>
[2025-02-16T17:39:35.371+0000] {taskinstance.py:2867} INFO - Starting attempt 3 of 3
[2025-02-16T17:39:35.384+0000] {taskinstance.py:2890} INFO - Executing <Task(PythonOperator): load_config> on 2025-02-16 17:25:22.072157+00:00
[2025-02-16T17:39:35.394+0000] {warnings.py:112} WARNING - /home/***/.local/lib/python3.12/site-packages/***/task/task_runner/standard_task_runner.py:70: DeprecationWarning: This process (pid=298) is multi-threaded, use of fork() may lead to deadlocks in the child.
  pid = os.fork()

[2025-02-16T17:39:35.397+0000] {standard_task_runner.py:72} INFO - Started process 314 to run task
[2025-02-16T17:39:35.398+0000] {standard_task_runner.py:104} INFO - Running: ['***', 'tasks', 'run', 'google_news_scraper', 'load_config', 'manual__2025-02-16T17:25:22.072157+00:00', '--job-id', '31', '--raw', '--subdir', 'DAGS_FOLDER/dag2.py', '--cfg-path', '/tmp/tmpe18ds6dt']
[2025-02-16T17:39:35.399+0000] {standard_task_runner.py:105} INFO - Job 31: Subtask load_config
[2025-02-16T17:39:35.445+0000] {task_command.py:467} INFO - Running <TaskInstance: google_news_scraper.load_config manual__2025-02-16T17:25:22.072157+00:00 [running]> on host b77df429da7c
[2025-02-16T17:39:35.526+0000] {taskinstance.py:3134} INFO - Exporting env vars: AIRFLOW_CTX_DAG_OWNER='***' AIRFLOW_CTX_DAG_ID='google_news_scraper' AIRFLOW_CTX_TASK_ID='load_config' AIRFLOW_CTX_EXECUTION_DATE='2025-02-16T17:25:22.072157+00:00' AIRFLOW_CTX_TRY_NUMBER='3' AIRFLOW_CTX_DAG_RUN_ID='manual__2025-02-16T17:25:22.072157+00:00'
[2025-02-16T17:39:35.528+0000] {logging_mixin.py:190} INFO - Task instance is in running state
[2025-02-16T17:39:35.528+0000] {logging_mixin.py:190} INFO -  Previous state of the Task instance: queued
[2025-02-16T17:39:35.529+0000] {logging_mixin.py:190} INFO - Current task name:load_config state:running start_date:2025-02-16 17:39:35.363841+00:00
[2025-02-16T17:39:35.529+0000] {logging_mixin.py:190} INFO - Dag name:google_news_scraper and current dag run status:running
[2025-02-16T17:39:35.530+0000] {taskinstance.py:732} INFO - ::endgroup::
[2025-02-16T17:39:35.530+0000] {logging_mixin.py:190} INFO - Current Working Directory: /opt/***
[2025-02-16T17:39:35.531+0000] {logging_mixin.py:190} INFO - config.json not found.
[2025-02-16T17:39:35.534+0000] {warnings.py:112} WARNING - <unknown>:1: SyntaxWarning: invalid escape sequence '\d'

[2025-02-16T17:39:35.531+0000] {taskinstance.py:3313} ERROR - Task failed with exception
Traceback (most recent call last):
  File "/home/airflow/.local/lib/python3.12/site-packages/airflow/models/taskinstance.py", line 768, in _execute_task
    result = _execute_callable(context=context, **execute_callable_kwargs)
             ^^^^^^^^^^^^^^^^^^^^^^^^^^^^^^^^^^^^^^^^^^^^^^^^^^^^^^^^^^^^^
  File "/home/airflow/.local/lib/python3.12/site-packages/airflow/models/taskinstance.py", line 734, in _execute_callable
    return ExecutionCallableRunner(
           ^^^^^^^^^^^^^^^^^^^^^^^^
  File "/home/airflow/.local/lib/python3.12/site-packages/airflow/utils/operator_helpers.py", line 252, in run
    return self.func(*args, **kwargs)
           ^^^^^^^^^^^^^^^^^^^^^^^^^^
  File "/home/airflow/.local/lib/python3.12/site-packages/airflow/models/baseoperator.py", line 424, in wrapper
    return func(self, *args, **kwargs)
           ^^^^^^^^^^^^^^^^^^^^^^^^^^^
  File "/home/airflow/.local/lib/python3.12/site-packages/airflow/operators/python.py", line 238, in execute
    return_value = self.execute_callable()
                   ^^^^^^^^^^^^^^^^^^^^^^^
  File "/home/airflow/.local/lib/python3.12/site-packages/airflow/operators/python.py", line 256, in execute_callable
    return runner.run(*self.op_args, **self.op_kwargs)
           ^^^^^^^^^^^^^^^^^^^^^^^^^^^^^^^^^^^^^^^^^^^
  File "/home/airflow/.local/lib/python3.12/site-packages/airflow/utils/operator_helpers.py", line 252, in run
    return self.func(*args, **kwargs)
           ^^^^^^^^^^^^^^^^^^^^^^^^^^
  File "/opt/airflow/dags/dag2.py", line 19, in load_config
    with open('airflow-docker\dags\config.json', 'r') as f:
         ^^^^^^^^^^^^^^^^^^^^^^^^^^^^^^^^^^^^^^^^^^^^
FileNotFoundError: [Errno 2] No such file or directory: 'airflow-docker\\dags\\config.json'
[2025-02-16T17:39:35.541+0000] {logging_mixin.py:190} INFO - Task instance in failure state
[2025-02-16T17:39:35.541+0000] {logging_mixin.py:190} INFO - Task start:2025-02-16 17:39:35.363841+00:00 end:2025-02-16 17:39:35.540851+00:00 duration:0.17701
[2025-02-16T17:39:35.542+0000] {logging_mixin.py:190} INFO - Task:<Task(PythonOperator): load_config> dag:<DAG: google_news_scraper> dagrun:<DagRun google_news_scraper @ 2025-02-16 17:25:22.072157+00:00: manual__2025-02-16T17:25:22.072157+00:00, state:running, queued_at: 2025-02-16 17:25:22.091487+00:00. externally triggered: True>
[2025-02-16T17:39:35.542+0000] {logging_mixin.py:190} INFO - Failure caused by [Errno 2] No such file or directory: '***-docker\\dags\\config.json'
[2025-02-16T17:39:35.543+0000] {taskinstance.py:1226} INFO - Marking task as FAILED. dag_id=google_news_scraper, task_id=load_config, run_id=manual__2025-02-16T17:25:22.072157+00:00, execution_date=20250216T172522, start_date=20250216T173935, end_date=20250216T173935
[2025-02-16T17:39:35.567+0000] {taskinstance.py:341} INFO - ::group::Post task execution logs
[2025-02-16T17:39:35.570+0000] {warnings.py:112} WARNING - <unknown>:1: SyntaxWarning: invalid escape sequence '\d'

[2025-02-16T17:39:35.568+0000] {standard_task_runner.py:124} ERROR - Failed to execute job 31 for task load_config ([Errno 2] No such file or directory: 'airflow-docker\\dags\\config.json'; 314)
Traceback (most recent call last):
  File "/home/airflow/.local/lib/python3.12/site-packages/airflow/task/task_runner/standard_task_runner.py", line 117, in _start_by_fork
    ret = args.func(args, dag=self.dag)
          ^^^^^^^^^^^^^^^^^^^^^^^^^^^^^
  File "/home/airflow/.local/lib/python3.12/site-packages/airflow/cli/cli_config.py", line 49, in command
    return func(*args, **kwargs)
           ^^^^^^^^^^^^^^^^^^^^^
  File "/home/airflow/.local/lib/python3.12/site-packages/airflow/utils/cli.py", line 116, in wrapper
    return f(*args, **kwargs)
           ^^^^^^^^^^^^^^^^^^
  File "/home/airflow/.local/lib/python3.12/site-packages/airflow/cli/commands/task_command.py", line 483, in task_run
    task_return_code = _run_task_by_selected_method(args, _dag, ti)
                       ^^^^^^^^^^^^^^^^^^^^^^^^^^^^^^^^^^^^^^^^^^^^
  File "/home/airflow/.local/lib/python3.12/site-packages/airflow/cli/commands/task_command.py", line 256, in _run_task_by_selected_method
    return _run_raw_task(args, ti)
           ^^^^^^^^^^^^^^^^^^^^^^^
  File "/home/airflow/.local/lib/python3.12/site-packages/airflow/cli/commands/task_command.py", line 341, in _run_raw_task
    return ti._run_raw_task(
           ^^^^^^^^^^^^^^^^^
  File "/home/airflow/.local/lib/python3.12/site-packages/airflow/utils/session.py", line 97, in wrapper
    return func(*args, session=session, **kwargs)
           ^^^^^^^^^^^^^^^^^^^^^^^^^^^^^^^^^^^^^^
  File "/home/airflow/.local/lib/python3.12/site-packages/airflow/models/taskinstance.py", line 3006, in _run_raw_task
    return _run_raw_task(
           ^^^^^^^^^^^^^^
  File "/home/airflow/.local/lib/python3.12/site-packages/airflow/models/taskinstance.py", line 274, in _run_raw_task
    TaskInstance._execute_task_with_callbacks(
  File "/home/airflow/.local/lib/python3.12/site-packages/airflow/models/taskinstance.py", line 3161, in _execute_task_with_callbacks
    result = self._execute_task(context, task_orig)
             ^^^^^^^^^^^^^^^^^^^^^^^^^^^^^^^^^^^^^^
  File "/home/airflow/.local/lib/python3.12/site-packages/airflow/models/taskinstance.py", line 3185, in _execute_task
    return _execute_task(self, context, task_orig)
           ^^^^^^^^^^^^^^^^^^^^^^^^^^^^^^^^^^^^^^^
  File "/home/airflow/.local/lib/python3.12/site-packages/airflow/models/taskinstance.py", line 768, in _execute_task
    result = _execute_callable(context=context, **execute_callable_kwargs)
             ^^^^^^^^^^^^^^^^^^^^^^^^^^^^^^^^^^^^^^^^^^^^^^^^^^^^^^^^^^^^^
  File "/home/airflow/.local/lib/python3.12/site-packages/airflow/models/taskinstance.py", line 734, in _execute_callable
    return ExecutionCallableRunner(
           ^^^^^^^^^^^^^^^^^^^^^^^^
  File "/home/airflow/.local/lib/python3.12/site-packages/airflow/utils/operator_helpers.py", line 252, in run
    return self.func(*args, **kwargs)
           ^^^^^^^^^^^^^^^^^^^^^^^^^^
  File "/home/airflow/.local/lib/python3.12/site-packages/airflow/models/baseoperator.py", line 424, in wrapper
    return func(self, *args, **kwargs)
           ^^^^^^^^^^^^^^^^^^^^^^^^^^^
  File "/home/airflow/.local/lib/python3.12/site-packages/airflow/operators/python.py", line 238, in execute
    return_value = self.execute_callable()
                   ^^^^^^^^^^^^^^^^^^^^^^^
  File "/home/airflow/.local/lib/python3.12/site-packages/airflow/operators/python.py", line 256, in execute_callable
    return runner.run(*self.op_args, **self.op_kwargs)
           ^^^^^^^^^^^^^^^^^^^^^^^^^^^^^^^^^^^^^^^^^^^
  File "/home/airflow/.local/lib/python3.12/site-packages/airflow/utils/operator_helpers.py", line 252, in run
    return self.func(*args, **kwargs)
           ^^^^^^^^^^^^^^^^^^^^^^^^^^
  File "/opt/airflow/dags/dag2.py", line 19, in load_config
    with open('airflow-docker\dags\config.json', 'r') as f:
         ^^^^^^^^^^^^^^^^^^^^^^^^^^^^^^^^^^^^^^^^^^^^
FileNotFoundError: [Errno 2] No such file or directory: 'airflow-docker\\dags\\config.json'
[2025-02-16T17:39:35.614+0000] {local_task_job_runner.py:266} INFO - Task exited with return code 1
[2025-02-16T17:39:35.648+0000] {taskinstance.py:3901} INFO - 0 downstream tasks scheduled from follow-on schedule check
[2025-02-16T17:39:35.653+0000] {local_task_job_runner.py:245} INFO - ::endgroup::
