[2025-02-18T10:47:46.841+0000] {local_task_job_runner.py:123} INFO - ::group::Pre task execution logs
[2025-02-18T10:47:46.867+0000] {taskinstance.py:2614} INFO - Dependencies all met for dep_context=non-requeueable deps ti=<TaskInstance: google_news_scraper.get_and_parse_articles scheduled__2025-02-17T00:00:00+00:00 [queued]>
[2025-02-18T10:47:46.882+0000] {taskinstance.py:2614} INFO - Dependencies all met for dep_context=requeueable deps ti=<TaskInstance: google_news_scraper.get_and_parse_articles scheduled__2025-02-17T00:00:00+00:00 [queued]>
[2025-02-18T10:47:46.883+0000] {taskinstance.py:2867} INFO - Starting attempt 1 of 3
[2025-02-18T10:47:46.900+0000] {taskinstance.py:2890} INFO - Executing <Task(PythonOperator): get_and_parse_articles> on 2025-02-17 00:00:00+00:00
[2025-02-18T10:47:46.911+0000] {warnings.py:112} WARNING - /home/***/.local/lib/python3.12/site-packages/***/task/task_runner/standard_task_runner.py:70: DeprecationWarning: This process (pid=112) is multi-threaded, use of fork() may lead to deadlocks in the child.
  pid = os.fork()

[2025-02-18T10:47:46.915+0000] {standard_task_runner.py:72} INFO - Started process 128 to run task
[2025-02-18T10:47:46.916+0000] {standard_task_runner.py:104} INFO - Running: ['***', 'tasks', 'run', 'google_news_scraper', 'get_and_parse_articles', 'scheduled__2025-02-17T00:00:00+00:00', '--job-id', '66', '--raw', '--subdir', 'DAGS_FOLDER/dag2.py', '--cfg-path', '/tmp/tmp3zlcrdro']
[2025-02-18T10:47:46.918+0000] {standard_task_runner.py:105} INFO - Job 66: Subtask get_and_parse_articles
[2025-02-18T10:47:46.972+0000] {task_command.py:467} INFO - Running <TaskInstance: google_news_scraper.get_and_parse_articles scheduled__2025-02-17T00:00:00+00:00 [running]> on host 9546a27fb76d
[2025-02-18T10:47:47.065+0000] {taskinstance.py:3134} INFO - Exporting env vars: AIRFLOW_CTX_DAG_OWNER='***' AIRFLOW_CTX_DAG_ID='google_news_scraper' AIRFLOW_CTX_TASK_ID='get_and_parse_articles' AIRFLOW_CTX_EXECUTION_DATE='2025-02-17T00:00:00+00:00' AIRFLOW_CTX_TRY_NUMBER='1' AIRFLOW_CTX_DAG_RUN_ID='scheduled__2025-02-17T00:00:00+00:00'
[2025-02-18T10:47:47.067+0000] {logging_mixin.py:190} INFO - Task instance is in running state
[2025-02-18T10:47:47.067+0000] {logging_mixin.py:190} INFO -  Previous state of the Task instance: queued
[2025-02-18T10:47:47.068+0000] {logging_mixin.py:190} INFO - Current task name:get_and_parse_articles state:running start_date:2025-02-18 10:47:46.868845+00:00
[2025-02-18T10:47:47.069+0000] {logging_mixin.py:190} INFO - Dag name:google_news_scraper and current dag run status:running
[2025-02-18T10:47:47.070+0000] {taskinstance.py:732} INFO - ::endgroup::
[2025-02-18T10:47:49.433+0000] {warnings.py:112} WARNING - /home/***/.local/lib/python3.12/site-packages/pymongo/_csot.py:119: UserWarning: MongoClient opened before fork. May not be entirely fork-safe, proceed with caution. See PyMongo's documentation for details: https://www.mongodb.com/docs/languages/python/pymongo-driver/current/faq/#is-pymongo-fork-safe-
  return func(self, *args, **kwargs)

[2025-02-18T10:48:18.454+0000] {taskinstance.py:3313} ERROR - Task failed with exception
Traceback (most recent call last):
  File "/home/airflow/.local/lib/python3.12/site-packages/airflow/models/taskinstance.py", line 768, in _execute_task
    result = _execute_callable(context=context, **execute_callable_kwargs)
             ^^^^^^^^^^^^^^^^^^^^^^^^^^^^^^^^^^^^^^^^^^^^^^^^^^^^^^^^^^^^^
  File "/home/airflow/.local/lib/python3.12/site-packages/airflow/models/taskinstance.py", line 734, in _execute_callable
    return ExecutionCallableRunner(
           ^^^^^^^^^^^^^^^^^^^^^^^^
  File "/home/airflow/.local/lib/python3.12/site-packages/airflow/utils/operator_helpers.py", line 252, in run
    return self.func(*args, **kwargs)
           ^^^^^^^^^^^^^^^^^^^^^^^^^^
  File "/home/airflow/.local/lib/python3.12/site-packages/airflow/models/baseoperator.py", line 424, in wrapper
    return func(self, *args, **kwargs)
           ^^^^^^^^^^^^^^^^^^^^^^^^^^^
  File "/home/airflow/.local/lib/python3.12/site-packages/airflow/operators/python.py", line 238, in execute
    return_value = self.execute_callable()
                   ^^^^^^^^^^^^^^^^^^^^^^^
  File "/home/airflow/.local/lib/python3.12/site-packages/airflow/operators/python.py", line 256, in execute_callable
    return runner.run(*self.op_args, **self.op_kwargs)
           ^^^^^^^^^^^^^^^^^^^^^^^^^^^^^^^^^^^^^^^^^^^
  File "/home/airflow/.local/lib/python3.12/site-packages/airflow/utils/operator_helpers.py", line 252, in run
    return self.func(*args, **kwargs)
           ^^^^^^^^^^^^^^^^^^^^^^^^^^
  File "/opt/airflow/dags/dag2.py", line 34, in get_and_parse_articles
    articles = parse_google_news(html)
               ^^^^^^^^^^^^^^^^^^^^^^^
  File "/opt/airflow/dags/google_news_scraper.py", line 163, in parse_google_news
    article_counter = get_next_article_id()  # Initialize counter from the last ID in the DB
                      ^^^^^^^^^^^^^^^^^^^^^
  File "/opt/airflow/dags/google_news_scraper.py", line 129, in get_next_article_id
    last_article = collection.find_one(sort=[("article_id", -1)])
                   ^^^^^^^^^^^^^^^^^^^^^^^^^^^^^^^^^^^^^^^^^^^^^^
  File "/home/airflow/.local/lib/python3.12/site-packages/pymongo/synchronous/collection.py", line 1755, in find_one
    for result in cursor.limit(-1):
                  ^^^^^^^^^^^^^^^^
  File "/home/airflow/.local/lib/python3.12/site-packages/pymongo/synchronous/cursor.py", line 1281, in __next__
    return self.next()
           ^^^^^^^^^^^
  File "/home/airflow/.local/lib/python3.12/site-packages/pymongo/synchronous/cursor.py", line 1257, in next
    if len(self._data) or self._refresh():
                          ^^^^^^^^^^^^^^^
  File "/home/airflow/.local/lib/python3.12/site-packages/pymongo/synchronous/cursor.py", line 1205, in _refresh
    self._send_message(q)
  File "/home/airflow/.local/lib/python3.12/site-packages/pymongo/synchronous/cursor.py", line 1100, in _send_message
    response = client._run_operation(
               ^^^^^^^^^^^^^^^^^^^^^^
  File "/home/airflow/.local/lib/python3.12/site-packages/pymongo/_csot.py", line 119, in csot_wrapper
    return func(self, *args, **kwargs)
           ^^^^^^^^^^^^^^^^^^^^^^^^^^^
  File "/home/airflow/.local/lib/python3.12/site-packages/pymongo/synchronous/mongo_client.py", line 1752, in _run_operation
    return self._retryable_read(
           ^^^^^^^^^^^^^^^^^^^^^
  File "/home/airflow/.local/lib/python3.12/site-packages/pymongo/synchronous/mongo_client.py", line 1861, in _retryable_read
    return self._retry_internal(
           ^^^^^^^^^^^^^^^^^^^^^
  File "/home/airflow/.local/lib/python3.12/site-packages/pymongo/_csot.py", line 119, in csot_wrapper
    return func(self, *args, **kwargs)
           ^^^^^^^^^^^^^^^^^^^^^^^^^^^
  File "/home/airflow/.local/lib/python3.12/site-packages/pymongo/synchronous/mongo_client.py", line 1828, in _retry_internal
    ).run()
      ^^^^^
  File "/home/airflow/.local/lib/python3.12/site-packages/pymongo/synchronous/mongo_client.py", line 2565, in run
    return self._read() if self._is_read else self._write()
           ^^^^^^^^^^^^
  File "/home/airflow/.local/lib/python3.12/site-packages/pymongo/synchronous/mongo_client.py", line 2700, in _read
    self._server = self._get_server()
                   ^^^^^^^^^^^^^^^^^^
  File "/home/airflow/.local/lib/python3.12/site-packages/pymongo/synchronous/mongo_client.py", line 2656, in _get_server
    return self._client._select_server(
           ^^^^^^^^^^^^^^^^^^^^^^^^^^^^
  File "/home/airflow/.local/lib/python3.12/site-packages/pymongo/synchronous/mongo_client.py", line 1647, in _select_server
    server = topology.select_server(
             ^^^^^^^^^^^^^^^^^^^^^^^
  File "/home/airflow/.local/lib/python3.12/site-packages/pymongo/synchronous/topology.py", line 402, in select_server
    server = self._select_server(
             ^^^^^^^^^^^^^^^^^^^^
  File "/home/airflow/.local/lib/python3.12/site-packages/pymongo/synchronous/topology.py", line 380, in _select_server
    servers = self.select_servers(
              ^^^^^^^^^^^^^^^^^^^^
  File "/home/airflow/.local/lib/python3.12/site-packages/pymongo/synchronous/topology.py", line 287, in select_servers
    server_descriptions = self._select_servers_loop(
                          ^^^^^^^^^^^^^^^^^^^^^^^^^^
  File "/home/airflow/.local/lib/python3.12/site-packages/pymongo/synchronous/topology.py", line 337, in _select_servers_loop
    raise ServerSelectionTimeoutError(
pymongo.errors.ServerSelectionTimeoutError: localhost:27017: [Errno 111] Connection refused (configured timeouts: socketTimeoutMS: 20000.0ms, connectTimeoutMS: 20000.0ms), Timeout: 30s, Topology Description: <TopologyDescription id: 67b4655154c77790dd44f810, topology_type: Unknown, servers: [<ServerDescription ('localhost', 27017) server_type: Unknown, rtt: None, error=AutoReconnect('localhost:27017: [Errno 111] Connection refused (configured timeouts: socketTimeoutMS: 20000.0ms, connectTimeoutMS: 20000.0ms)')>]>
[2025-02-18T10:48:18.482+0000] {logging_mixin.py:190} INFO - Task instance in failure state
[2025-02-18T10:48:18.483+0000] {logging_mixin.py:190} INFO - Task start:2025-02-18 10:47:46.868845+00:00 end:2025-02-18 10:48:18.482065+00:00 duration:31.61322
[2025-02-18T10:48:18.485+0000] {logging_mixin.py:190} INFO - Task:<Task(PythonOperator): get_and_parse_articles> dag:<DAG: google_news_scraper> dagrun:<DagRun google_news_scraper @ 2025-02-17 00:00:00+00:00: scheduled__2025-02-17T00:00:00+00:00, state:running, queued_at: 2025-02-18 10:47:32.055069+00:00. externally triggered: False>
[2025-02-18T10:48:18.485+0000] {logging_mixin.py:190} INFO - Failure caused by localhost:27017: [Errno 111] Connection refused (configured timeouts: socketTimeoutMS: 20000.0ms, connectTimeoutMS: 20000.0ms), Timeout: 30s, Topology Description: <TopologyDescription id: 67b4655154c77790dd44f810, topology_type: Unknown, servers: [<ServerDescription ('localhost', 27017) server_type: Unknown, rtt: None, error=AutoReconnect('localhost:27017: [Errno 111] Connection refused (configured timeouts: socketTimeoutMS: 20000.0ms, connectTimeoutMS: 20000.0ms)')>]>
[2025-02-18T10:48:18.487+0000] {taskinstance.py:1226} INFO - Marking task as UP_FOR_RETRY. dag_id=google_news_scraper, task_id=get_and_parse_articles, run_id=scheduled__2025-02-17T00:00:00+00:00, execution_date=20250217T000000, start_date=20250218T104746, end_date=20250218T104818
[2025-02-18T10:48:18.529+0000] {taskinstance.py:341} INFO - ::group::Post task execution logs
[2025-02-18T10:48:18.530+0000] {standard_task_runner.py:124} ERROR - Failed to execute job 66 for task get_and_parse_articles (localhost:27017: [Errno 111] Connection refused (configured timeouts: socketTimeoutMS: 20000.0ms, connectTimeoutMS: 20000.0ms), Timeout: 30s, Topology Description: <TopologyDescription id: 67b4655154c77790dd44f810, topology_type: Unknown, servers: [<ServerDescription ('localhost', 27017) server_type: Unknown, rtt: None, error=AutoReconnect('localhost:27017: [Errno 111] Connection refused (configured timeouts: socketTimeoutMS: 20000.0ms, connectTimeoutMS: 20000.0ms)')>]>; 128)
Traceback (most recent call last):
  File "/home/airflow/.local/lib/python3.12/site-packages/airflow/task/task_runner/standard_task_runner.py", line 117, in _start_by_fork
    ret = args.func(args, dag=self.dag)
          ^^^^^^^^^^^^^^^^^^^^^^^^^^^^^
  File "/home/airflow/.local/lib/python3.12/site-packages/airflow/cli/cli_config.py", line 49, in command
    return func(*args, **kwargs)
           ^^^^^^^^^^^^^^^^^^^^^
  File "/home/airflow/.local/lib/python3.12/site-packages/airflow/utils/cli.py", line 116, in wrapper
    return f(*args, **kwargs)
           ^^^^^^^^^^^^^^^^^^
  File "/home/airflow/.local/lib/python3.12/site-packages/airflow/cli/commands/task_command.py", line 483, in task_run
    task_return_code = _run_task_by_selected_method(args, _dag, ti)
                       ^^^^^^^^^^^^^^^^^^^^^^^^^^^^^^^^^^^^^^^^^^^^
  File "/home/airflow/.local/lib/python3.12/site-packages/airflow/cli/commands/task_command.py", line 256, in _run_task_by_selected_method
    return _run_raw_task(args, ti)
           ^^^^^^^^^^^^^^^^^^^^^^^
  File "/home/airflow/.local/lib/python3.12/site-packages/airflow/cli/commands/task_command.py", line 341, in _run_raw_task
    return ti._run_raw_task(
           ^^^^^^^^^^^^^^^^^
  File "/home/airflow/.local/lib/python3.12/site-packages/airflow/utils/session.py", line 97, in wrapper
    return func(*args, session=session, **kwargs)
           ^^^^^^^^^^^^^^^^^^^^^^^^^^^^^^^^^^^^^^
  File "/home/airflow/.local/lib/python3.12/site-packages/airflow/models/taskinstance.py", line 3006, in _run_raw_task
    return _run_raw_task(
           ^^^^^^^^^^^^^^
  File "/home/airflow/.local/lib/python3.12/site-packages/airflow/models/taskinstance.py", line 274, in _run_raw_task
    TaskInstance._execute_task_with_callbacks(
  File "/home/airflow/.local/lib/python3.12/site-packages/airflow/models/taskinstance.py", line 3161, in _execute_task_with_callbacks
    result = self._execute_task(context, task_orig)
             ^^^^^^^^^^^^^^^^^^^^^^^^^^^^^^^^^^^^^^
  File "/home/airflow/.local/lib/python3.12/site-packages/airflow/models/taskinstance.py", line 3185, in _execute_task
    return _execute_task(self, context, task_orig)
           ^^^^^^^^^^^^^^^^^^^^^^^^^^^^^^^^^^^^^^^
  File "/home/airflow/.local/lib/python3.12/site-packages/airflow/models/taskinstance.py", line 768, in _execute_task
    result = _execute_callable(context=context, **execute_callable_kwargs)
             ^^^^^^^^^^^^^^^^^^^^^^^^^^^^^^^^^^^^^^^^^^^^^^^^^^^^^^^^^^^^^
  File "/home/airflow/.local/lib/python3.12/site-packages/airflow/models/taskinstance.py", line 734, in _execute_callable
    return ExecutionCallableRunner(
           ^^^^^^^^^^^^^^^^^^^^^^^^
  File "/home/airflow/.local/lib/python3.12/site-packages/airflow/utils/operator_helpers.py", line 252, in run
    return self.func(*args, **kwargs)
           ^^^^^^^^^^^^^^^^^^^^^^^^^^
  File "/home/airflow/.local/lib/python3.12/site-packages/airflow/models/baseoperator.py", line 424, in wrapper
    return func(self, *args, **kwargs)
           ^^^^^^^^^^^^^^^^^^^^^^^^^^^
  File "/home/airflow/.local/lib/python3.12/site-packages/airflow/operators/python.py", line 238, in execute
    return_value = self.execute_callable()
                   ^^^^^^^^^^^^^^^^^^^^^^^
  File "/home/airflow/.local/lib/python3.12/site-packages/airflow/operators/python.py", line 256, in execute_callable
    return runner.run(*self.op_args, **self.op_kwargs)
           ^^^^^^^^^^^^^^^^^^^^^^^^^^^^^^^^^^^^^^^^^^^
  File "/home/airflow/.local/lib/python3.12/site-packages/airflow/utils/operator_helpers.py", line 252, in run
    return self.func(*args, **kwargs)
           ^^^^^^^^^^^^^^^^^^^^^^^^^^
  File "/opt/airflow/dags/dag2.py", line 34, in get_and_parse_articles
    articles = parse_google_news(html)
               ^^^^^^^^^^^^^^^^^^^^^^^
  File "/opt/airflow/dags/google_news_scraper.py", line 163, in parse_google_news
    article_counter = get_next_article_id()  # Initialize counter from the last ID in the DB
                      ^^^^^^^^^^^^^^^^^^^^^
  File "/opt/airflow/dags/google_news_scraper.py", line 129, in get_next_article_id
    last_article = collection.find_one(sort=[("article_id", -1)])
                   ^^^^^^^^^^^^^^^^^^^^^^^^^^^^^^^^^^^^^^^^^^^^^^
  File "/home/airflow/.local/lib/python3.12/site-packages/pymongo/synchronous/collection.py", line 1755, in find_one
    for result in cursor.limit(-1):
                  ^^^^^^^^^^^^^^^^
  File "/home/airflow/.local/lib/python3.12/site-packages/pymongo/synchronous/cursor.py", line 1281, in __next__
    return self.next()
           ^^^^^^^^^^^
  File "/home/airflow/.local/lib/python3.12/site-packages/pymongo/synchronous/cursor.py", line 1257, in next
    if len(self._data) or self._refresh():
                          ^^^^^^^^^^^^^^^
  File "/home/airflow/.local/lib/python3.12/site-packages/pymongo/synchronous/cursor.py", line 1205, in _refresh
    self._send_message(q)
  File "/home/airflow/.local/lib/python3.12/site-packages/pymongo/synchronous/cursor.py", line 1100, in _send_message
    response = client._run_operation(
               ^^^^^^^^^^^^^^^^^^^^^^
  File "/home/airflow/.local/lib/python3.12/site-packages/pymongo/_csot.py", line 119, in csot_wrapper
    return func(self, *args, **kwargs)
           ^^^^^^^^^^^^^^^^^^^^^^^^^^^
  File "/home/airflow/.local/lib/python3.12/site-packages/pymongo/synchronous/mongo_client.py", line 1752, in _run_operation
    return self._retryable_read(
           ^^^^^^^^^^^^^^^^^^^^^
  File "/home/airflow/.local/lib/python3.12/site-packages/pymongo/synchronous/mongo_client.py", line 1861, in _retryable_read
    return self._retry_internal(
           ^^^^^^^^^^^^^^^^^^^^^
  File "/home/airflow/.local/lib/python3.12/site-packages/pymongo/_csot.py", line 119, in csot_wrapper
    return func(self, *args, **kwargs)
           ^^^^^^^^^^^^^^^^^^^^^^^^^^^
  File "/home/airflow/.local/lib/python3.12/site-packages/pymongo/synchronous/mongo_client.py", line 1828, in _retry_internal
    ).run()
      ^^^^^
  File "/home/airflow/.local/lib/python3.12/site-packages/pymongo/synchronous/mongo_client.py", line 2565, in run
    return self._read() if self._is_read else self._write()
           ^^^^^^^^^^^^
  File "/home/airflow/.local/lib/python3.12/site-packages/pymongo/synchronous/mongo_client.py", line 2700, in _read
    self._server = self._get_server()
                   ^^^^^^^^^^^^^^^^^^
  File "/home/airflow/.local/lib/python3.12/site-packages/pymongo/synchronous/mongo_client.py", line 2656, in _get_server
    return self._client._select_server(
           ^^^^^^^^^^^^^^^^^^^^^^^^^^^^
  File "/home/airflow/.local/lib/python3.12/site-packages/pymongo/synchronous/mongo_client.py", line 1647, in _select_server
    server = topology.select_server(
             ^^^^^^^^^^^^^^^^^^^^^^^
  File "/home/airflow/.local/lib/python3.12/site-packages/pymongo/synchronous/topology.py", line 402, in select_server
    server = self._select_server(
             ^^^^^^^^^^^^^^^^^^^^
  File "/home/airflow/.local/lib/python3.12/site-packages/pymongo/synchronous/topology.py", line 380, in _select_server
    servers = self.select_servers(
              ^^^^^^^^^^^^^^^^^^^^
  File "/home/airflow/.local/lib/python3.12/site-packages/pymongo/synchronous/topology.py", line 287, in select_servers
    server_descriptions = self._select_servers_loop(
                          ^^^^^^^^^^^^^^^^^^^^^^^^^^
  File "/home/airflow/.local/lib/python3.12/site-packages/pymongo/synchronous/topology.py", line 337, in _select_servers_loop
    raise ServerSelectionTimeoutError(
pymongo.errors.ServerSelectionTimeoutError: localhost:27017: [Errno 111] Connection refused (configured timeouts: socketTimeoutMS: 20000.0ms, connectTimeoutMS: 20000.0ms), Timeout: 30s, Topology Description: <TopologyDescription id: 67b4655154c77790dd44f810, topology_type: Unknown, servers: [<ServerDescription ('localhost', 27017) server_type: Unknown, rtt: None, error=AutoReconnect('localhost:27017: [Errno 111] Connection refused (configured timeouts: socketTimeoutMS: 20000.0ms, connectTimeoutMS: 20000.0ms)')>]>
[2025-02-18T10:48:18.577+0000] {local_task_job_runner.py:266} INFO - Task exited with return code 1
[2025-02-18T10:48:18.599+0000] {taskinstance.py:3901} INFO - 0 downstream tasks scheduled from follow-on schedule check
[2025-02-18T10:48:18.602+0000] {local_task_job_runner.py:245} INFO - ::endgroup::
[2025-02-18T14:58:28.882+0000] {local_task_job_runner.py:123} INFO - ::group::Pre task execution logs
[2025-02-18T14:58:28.902+0000] {taskinstance.py:2614} INFO - Dependencies all met for dep_context=non-requeueable deps ti=<TaskInstance: google_news_scraper.get_and_parse_articles scheduled__2025-02-17T00:00:00+00:00 [queued]>
[2025-02-18T14:58:28.912+0000] {taskinstance.py:2614} INFO - Dependencies all met for dep_context=requeueable deps ti=<TaskInstance: google_news_scraper.get_and_parse_articles scheduled__2025-02-17T00:00:00+00:00 [queued]>
[2025-02-18T14:58:28.913+0000] {taskinstance.py:2867} INFO - Starting attempt 1 of 3
[2025-02-18T14:58:28.925+0000] {taskinstance.py:2890} INFO - Executing <Task(PythonOperator): get_and_parse_articles> on 2025-02-17 00:00:00+00:00
[2025-02-18T14:58:28.935+0000] {warnings.py:112} WARNING - /home/***/.local/lib/python3.12/site-packages/***/task/task_runner/standard_task_runner.py:70: DeprecationWarning: This process (pid=161) is multi-threaded, use of fork() may lead to deadlocks in the child.
  pid = os.fork()

[2025-02-18T14:58:28.937+0000] {standard_task_runner.py:72} INFO - Started process 190 to run task
[2025-02-18T14:58:28.937+0000] {standard_task_runner.py:104} INFO - Running: ['***', 'tasks', 'run', 'google_news_scraper', 'get_and_parse_articles', 'scheduled__2025-02-17T00:00:00+00:00', '--job-id', '19', '--raw', '--subdir', 'DAGS_FOLDER/dag2.py', '--cfg-path', '/tmp/tmpuvmsxevw']
[2025-02-18T14:58:28.938+0000] {standard_task_runner.py:105} INFO - Job 19: Subtask get_and_parse_articles
[2025-02-18T14:58:28.994+0000] {task_command.py:467} INFO - Running <TaskInstance: google_news_scraper.get_and_parse_articles scheduled__2025-02-17T00:00:00+00:00 [running]> on host 695150105d31
[2025-02-18T14:58:29.076+0000] {taskinstance.py:3134} INFO - Exporting env vars: AIRFLOW_CTX_DAG_OWNER='***' AIRFLOW_CTX_DAG_ID='google_news_scraper' AIRFLOW_CTX_TASK_ID='get_and_parse_articles' AIRFLOW_CTX_EXECUTION_DATE='2025-02-17T00:00:00+00:00' AIRFLOW_CTX_TRY_NUMBER='1' AIRFLOW_CTX_DAG_RUN_ID='scheduled__2025-02-17T00:00:00+00:00'
[2025-02-18T14:58:29.078+0000] {logging_mixin.py:190} INFO - Task instance is in running state
[2025-02-18T14:58:29.079+0000] {logging_mixin.py:190} INFO -  Previous state of the Task instance: queued
[2025-02-18T14:58:29.079+0000] {logging_mixin.py:190} INFO - Current task name:get_and_parse_articles state:running start_date:2025-02-18 14:58:28.903042+00:00
[2025-02-18T14:58:29.080+0000] {logging_mixin.py:190} INFO - Dag name:google_news_scraper and current dag run status:running
[2025-02-18T14:58:29.081+0000] {taskinstance.py:732} INFO - ::endgroup::
[2025-02-18T14:58:29.909+0000] {logging_mixin.py:190} INFO - https://news.google.com/read/CBMihgJBVV95cUxORTBZbDBuaHpVTVl6bWczTzJZWUZZQlptYmpwWVhnU2cxYXMyQ3pEWTRPZHYwNGcwR1BBSEJRMzB3Vi0zNnp4UHY3UmFmdG43aDFNcURIZFBQN2NnLUV2SkxfUjltcWxiSGJYWG1WY1hOaUxIcTdCWjktdnNiUmtvRHBxMFpMekRoMXdZTjVSSnBkbDhwUzdDN2E5TTlTREQtSWp0bmV2NWhpQ2VCNjZBbzhCR0VEY1dFVC1BcEZNVUI3RURLNUxObEc0QTdwNkNSSGpXSG1EbnV4cjhfdzh5TDFOWG9SeGpxUEUxMmRiNDFkVkszQ0gxN1lwc0JGaUtWZ2J6ajV3?hl=en-IN&gl=IN&ceid=IN%3Aen
[2025-02-18T14:58:29.910+0000] {logger.py:11} INFO - ====== WebDriver manager ======
[2025-02-18T14:58:29.931+0000] {logger.py:11} INFO - Get LATEST chromedriver version for google-chrome
[2025-02-18T14:58:30.406+0000] {logger.py:11} INFO - About to download new driver from https://chromedriver.storage.googleapis.com/114.0.5735.90/chromedriver_linux64.zip
[2025-02-18T14:58:30.751+0000] {logger.py:11} INFO - Driver downloading response is 200
[2025-02-18T14:58:35.867+0000] {logger.py:11} INFO - Get LATEST chromedriver version for google-chrome
[2025-02-18T14:58:36.354+0000] {logger.py:11} INFO - Get LATEST chromedriver version for google-chrome
[2025-02-18T14:58:36.711+0000] {logger.py:11} INFO - Driver has been saved in cache [/home/***/.wdm/drivers/chromedriver/linux64/114.0.5735.90]
[2025-02-18T14:58:36.725+0000] {logging_mixin.py:190} INFO - Error with Selenium: Message: Service /home/***/.wdm/drivers/chromedriver/linux64/114.0.5735.90/chromedriver unexpectedly exited. Status code was: 127
[2025-02-18T14:58:36.969+0000] {logging_mixin.py:190} INFO - [INFO] Downloaded thumbnail: thumbnail_1.jpg
[2025-02-18T14:58:36.971+0000] {logging_mixin.py:190} INFO - New article added with ID: 1
[2025-02-18T14:58:36.972+0000] {logging_mixin.py:190} INFO - https://news.google.com/read/CBMixAFBVV95cUxOdlRyczNXc3B6RW5jN2ZuNjhkeHRzZGdzVVZLYnA4WGtpTVE3VmJwYThGeTZwemdnZTkxcVowNTJueFN4YV94S28xSjlpZ0pndF9ZWU5nY1JmMU9OVmpKN3l1YndQdXZfY1J0VjdsRl9qaDE2NE5pbHVMNDVkb0drLWM1TEpqdFYtNXFkUWpwTVZJMFZmMUtCZDhJdWJHWlVVMEdTdEVxOXR3cUFwQ3dYZU5hQVdKUzYxWXNBMVF3enVMOTFo0gHKAUFVX3lxTFBmRkVyWU11M0JEMGdvX3VzNllIODd5WHlNTTFNUGRCWWwxUlM3RnBYdk10OGFlSERnc1phaWFqWGZxVTFTa1JZalcyOXhSLVdNNnBiQVZFRkc0TDRwb2UwaERTVFBGVGNwNUlQOXRnZ2tFT1dndWlBM052SmdGanNXMGs1cFM1b3l6T1hyQ21ZVkxycXpXOGp3TXYxQmRWbnJWYUZsV0J3VzBNRV9OT1JKaG9WU2VSTEFlTVlxc1VYSXp1LWJQa2YwWFE?hl=en-IN&gl=IN&ceid=IN%3Aen
[2025-02-18T14:58:36.974+0000] {logger.py:11} INFO - ====== WebDriver manager ======
[2025-02-18T14:58:36.997+0000] {logger.py:11} INFO - Get LATEST chromedriver version for google-chrome
[2025-02-18T14:58:36.090+0000] {logger.py:11} INFO - About to download new driver from https://chromedriver.storage.googleapis.com/114.0.5735.90/chromedriver_linux64.zip
[2025-02-18T14:58:36.429+0000] {logger.py:11} INFO - Driver downloading response is 200
[2025-02-18T14:58:39.033+0000] {logger.py:11} INFO - Get LATEST chromedriver version for google-chrome
[2025-02-18T14:58:39.530+0000] {logger.py:11} INFO - Get LATEST chromedriver version for google-chrome
[2025-02-18T14:58:40.238+0000] {logger.py:11} INFO - Driver has been saved in cache [/home/***/.wdm/drivers/chromedriver/linux64/114.0.5735.90]
[2025-02-18T14:58:40.255+0000] {logging_mixin.py:190} INFO - Error with Selenium: Message: Service /home/***/.wdm/drivers/chromedriver/linux64/114.0.5735.90/chromedriver unexpectedly exited. Status code was: 127
[2025-02-18T14:58:40.657+0000] {logging_mixin.py:190} INFO - [INFO] Downloaded thumbnail: thumbnail_2.jpg
[2025-02-18T14:58:40.658+0000] {logging_mixin.py:190} INFO - New article added with ID: 2
[2025-02-18T14:58:40.659+0000] {logging_mixin.py:190} INFO - https://news.google.com/read/CBMipgFBVV95cUxNMzBOTGxDUjVlV3BiTFY1Vjl4eHRsYnp0WlBESW1qYXROVUVLbEFOUndEdEtxeUpUelRjUjdlcEM0dVhjR1E1QTlKWHdvTEZlazY1MXV0TGY1RDFfbURhblNDTkVuZFpoN1pOWGlsSzh2QW1yZzVYaTlnZ3RrZWIyYnJoY3pQdGlhcHQxcmc3OTNGS0ZWYUtaOXFvS0o0TENrR09YVFdn?hl=en-IN&gl=IN&ceid=IN%3Aen
[2025-02-18T14:58:40.660+0000] {logger.py:11} INFO - ====== WebDriver manager ======
[2025-02-18T14:58:40.674+0000] {logger.py:11} INFO - Get LATEST chromedriver version for google-chrome
[2025-02-18T14:58:41.277+0000] {logger.py:11} INFO - About to download new driver from https://chromedriver.storage.googleapis.com/114.0.5735.90/chromedriver_linux64.zip
[2025-02-18T14:58:41.747+0000] {logger.py:11} INFO - Driver downloading response is 200
[2025-02-18T14:58:44.747+0000] {logger.py:11} INFO - Get LATEST chromedriver version for google-chrome
[2025-02-18T14:58:45.207+0000] {logger.py:11} INFO - Get LATEST chromedriver version for google-chrome
[2025-02-18T14:58:45.637+0000] {logger.py:11} INFO - Driver has been saved in cache [/home/***/.wdm/drivers/chromedriver/linux64/114.0.5735.90]
[2025-02-18T14:58:45.651+0000] {logging_mixin.py:190} INFO - Error with Selenium: Message: Service /home/***/.wdm/drivers/chromedriver/linux64/114.0.5735.90/chromedriver unexpectedly exited. Status code was: 127
[2025-02-18T14:58:46.358+0000] {logging_mixin.py:190} INFO - [INFO] Downloaded thumbnail: thumbnail_3.jpg
[2025-02-18T14:58:46.359+0000] {logging_mixin.py:190} INFO - New article added with ID: 3
[2025-02-18T14:58:46.360+0000] {logging_mixin.py:190} INFO - https://news.google.com/read/CBMiuAFBVV95cUxQdmlsaGxCUFNWd2o1VGxmRHF3MDRqeUw0RzBWVHIyV2I2Z09OYnBOMEplUHlJcExLVVk3aWo5ZDVvWVVGdEMzN1Zuam00b1JBOFl6bGR0OUhQcXhTNGJObk93RmxlWlg2eU90cFliaERZN05lVWF5SlVMMHBXVVp2YVVkS0tDcHhRNmhQQ1VFZnRXaFVXNzltUUt1MlpzMHhGTFhkSnZmQ0NSbVFXYXN3STRIYjVoUXJN?hl=en-IN&gl=IN&ceid=IN%3Aen
[2025-02-18T14:58:46.360+0000] {logger.py:11} INFO - ====== WebDriver manager ======
[2025-02-18T14:58:46.381+0000] {logger.py:11} INFO - Get LATEST chromedriver version for google-chrome
[2025-02-18T14:58:46.738+0000] {logger.py:11} INFO - About to download new driver from https://chromedriver.storage.googleapis.com/114.0.5735.90/chromedriver_linux64.zip
[2025-02-18T14:58:47.103+0000] {logger.py:11} INFO - Driver downloading response is 200
[2025-02-18T14:59:01.217+0000] {logger.py:11} INFO - Get LATEST chromedriver version for google-chrome
[2025-02-18T14:59:01.706+0000] {logger.py:11} INFO - Get LATEST chromedriver version for google-chrome
[2025-02-18T14:59:02.122+0000] {logger.py:11} INFO - Driver has been saved in cache [/home/***/.wdm/drivers/chromedriver/linux64/114.0.5735.90]
[2025-02-18T14:59:02.136+0000] {logging_mixin.py:190} INFO - Error with Selenium: Message: Service /home/***/.wdm/drivers/chromedriver/linux64/114.0.5735.90/chromedriver unexpectedly exited. Status code was: 127
[2025-02-18T14:59:02.337+0000] {logging_mixin.py:190} INFO - [INFO] Downloaded thumbnail: thumbnail_4.jpg
[2025-02-18T14:59:02.341+0000] {logging_mixin.py:190} INFO - New article added with ID: 4
[2025-02-18T14:59:02.343+0000] {logging_mixin.py:190} INFO - https://news.google.com/read/CBMi4wFBVV95cUxPTVhOb1lrc0dZbHNZZS1QVjl5WUlFbnNieS1tdnVjZnRJblBLVUprVU94aDljNkJiemw4LVVrWk1JcldBVkNPNTlnWThzZlhtbUNVUTIxb0YtN2lCcGI4YVFvWlR0VXdXSkIyNm9fLUNLVlEzYWJSVEtIQVV0OGlXNV9OcXAyTVJnNFdISUtjQ2Ezd1NCTmVMRXJCbW9GeFFjaExIbnUtb2xxaG9FcWwwTzc0Tnl4NkNsX2stbV96QUNsSVFiemhtOVV6Q3g0ellzeENnSjRueThPYmdPYXJyZFdwTdIB6AFBVV95cUxQNThzVnk1bFhibV9ZNnl2M2ZTajhkN3ZlM3hMR2ZISlFWWDFJaExQMWtoRWN5NldLUmJfTGE1NEx6R19jUElVTnNEaXNZWXpZSDdOcjNLNjJfamE1NzlZRVlRTGppTEtYa29iRV9MQjg2YnBqZW5wQldzTUxaR0l6RjFtWFFXMFN5U2hPMTNRWHFLS3RLellKbGc0Wk03RWNkR2tSVU1UYTNJUTFzQjlsMFdvUW9FT3otYW02b1laWm1SbXU5SHJOeXRXcUpweDYyMHlqa04zYnpZam9Qa2d3eU8xbzhhLW9l?hl=en-IN&gl=IN&ceid=IN%3Aen
[2025-02-18T14:59:02.344+0000] {logger.py:11} INFO - ====== WebDriver manager ======
[2025-02-18T14:59:02.365+0000] {logger.py:11} INFO - Get LATEST chromedriver version for google-chrome
[2025-02-18T14:59:02.762+0000] {logger.py:11} INFO - About to download new driver from https://chromedriver.storage.googleapis.com/114.0.5735.90/chromedriver_linux64.zip
[2025-02-18T14:59:03.411+0000] {logger.py:11} INFO - Driver downloading response is 200
[2025-02-18T14:59:05.837+0000] {logging_mixin.py:190} INFO - Error with Selenium: ('Connection broken: IncompleteRead(1140966 bytes read, 6266284 more expected)', IncompleteRead(1140966 bytes read, 6266284 more expected))
[2025-02-18T14:59:06.091+0000] {logging_mixin.py:190} INFO - [INFO] Downloaded thumbnail: thumbnail_5.jpg
[2025-02-18T14:59:06.092+0000] {logging_mixin.py:190} INFO - New article added with ID: 5
[2025-02-18T14:59:06.093+0000] {logging_mixin.py:190} INFO - https://news.google.com/read/CBMi_gFBVV95cUxPUzFvMThLeGk1RzJRa2hWeVlDNGFFSkkxTlA1VWNBa0hZenAyRFJ6Z3NubHBuSlNucjRTT3hMM1VycVRLbk5SZ29tWTJ5M2xYYlQyS3FxUmZ6SEFhaWVKbVJvMlVzS01vSW9ybTBMdnBEcmctNEJ6UTRkTXdUUko0eVppZndMVFlyYWxvZG9lR3oxbXBMM29DYXNkYUxWR3FpWDQwNUltaHAxeTFjUXdHeUZ6MlNBdlpid0dGRDExTm9JeWlOaWlieXZsTFJadW9pVVl3bTFKRFYxd0RTSzVPSFBrLWJSR0Z2UlNETjlwMGVRV0NfZ3o1Tk4tNmVSQQ?hl=en-IN&gl=IN&ceid=IN%3Aen
[2025-02-18T14:59:06.094+0000] {logger.py:11} INFO - ====== WebDriver manager ======
[2025-02-18T14:59:06.107+0000] {logger.py:11} INFO - Get LATEST chromedriver version for google-chrome
[2025-02-18T14:59:06.422+0000] {logger.py:11} INFO - About to download new driver from https://chromedriver.storage.googleapis.com/114.0.5735.90/chromedriver_linux64.zip
[2025-02-18T14:59:06.754+0000] {logger.py:11} INFO - Driver downloading response is 200
[2025-02-18T14:59:08.956+0000] {logger.py:11} INFO - Get LATEST chromedriver version for google-chrome
[2025-02-18T14:59:09.458+0000] {logger.py:11} INFO - Get LATEST chromedriver version for google-chrome
[2025-02-18T14:59:09.783+0000] {logger.py:11} INFO - Driver has been saved in cache [/home/***/.wdm/drivers/chromedriver/linux64/114.0.5735.90]
[2025-02-18T14:59:09.799+0000] {logging_mixin.py:190} INFO - Error with Selenium: Message: Service /home/***/.wdm/drivers/chromedriver/linux64/114.0.5735.90/chromedriver unexpectedly exited. Status code was: 127
[2025-02-18T14:59:10.137+0000] {logging_mixin.py:190} INFO - [INFO] Downloaded thumbnail: thumbnail_6.jpg
[2025-02-18T14:59:10.138+0000] {logging_mixin.py:190} INFO - New article added with ID: 6
[2025-02-18T14:59:10.139+0000] {logging_mixin.py:190} INFO - https://news.google.com/read/CBMi2gFBVV95cUxPSkdNcThXYTExR0pfYjRhbU1sdmhFSWRrV1ZFN29RUDAyUWM3WElOUGJwaXNBYmdRSGFpcVFUcUNXWW5Za3o5bzVUaklLZVpuZ25wM1M5RWFZMkRMSmFreEFid3JMc1VlZFpubGxiRUZFRG1vTGh6Vkp4YVRiaF9rYVJIYjQ4clNVMDFaMWljeUVkd1NyUjV3eTJGNWNvdVF0SnZGZWk5REJOeUM5YXc0R21jTHp4cHpJR0VXZ2hsWktXRVdJS1RDTmFCcE9uT1M1bVFPLUgxb2JqQQ?hl=en-IN&gl=IN&ceid=IN%3Aen
[2025-02-18T14:59:10.140+0000] {logger.py:11} INFO - ====== WebDriver manager ======
[2025-02-18T14:59:10.158+0000] {logger.py:11} INFO - Get LATEST chromedriver version for google-chrome
[2025-02-18T14:59:10.528+0000] {logger.py:11} INFO - About to download new driver from https://chromedriver.storage.googleapis.com/114.0.5735.90/chromedriver_linux64.zip
[2025-02-18T14:59:10.873+0000] {logger.py:11} INFO - Driver downloading response is 200
[2025-02-18T14:59:15.754+0000] {logger.py:11} INFO - Get LATEST chromedriver version for google-chrome
[2025-02-18T14:59:16.195+0000] {logger.py:11} INFO - Get LATEST chromedriver version for google-chrome
[2025-02-18T14:59:16.548+0000] {logger.py:11} INFO - Driver has been saved in cache [/home/***/.wdm/drivers/chromedriver/linux64/114.0.5735.90]
[2025-02-18T14:59:16.562+0000] {logging_mixin.py:190} INFO - Error with Selenium: Message: Service /home/***/.wdm/drivers/chromedriver/linux64/114.0.5735.90/chromedriver unexpectedly exited. Status code was: 127
[2025-02-18T14:59:16.748+0000] {logging_mixin.py:190} INFO - [INFO] Downloaded thumbnail: thumbnail_7.jpg
[2025-02-18T14:59:16.749+0000] {logging_mixin.py:190} INFO - New article added with ID: 7
[2025-02-18T14:59:16.750+0000] {logging_mixin.py:190} INFO - https://news.google.com/read/CBMizgFBVV95cUxQUDFBWDVyNmpxQzVFVldOU3RYNVhpSDFLNkxQWHJXenBwNjBTZDJRTlhSZTAzMlNZREkyRDNOaE5aRVp1VktTU0pyc2xtWmR3a0V4U0laUTVPb2ZMdmcycUZQbTlscHlRd2lXT245T0lzU3h4TkhXUHVFYnhwTXZ4SVRsbFQ3R0YwckwtM1gyRzdZMmdtbDB2WWxJcUl2NEsySTJkZ2toLXo3VDFrUWhDS3pva2pPS2duMGVZdTRrMk00amNjWEVDNFdfamR1Z9IB1gFBVV95cUxPOXNXS3pQQlhQZlhtVHNQeEV3TzdSdHV1OVc2alhlWTh3MzNhcDh0ZmNWbEllRlBSMy1ZSkdMbU9iU1pGeFU3ejd1Mk9kbWN5RUJLbS1YVlJtVndmM3VIZGNuYVNqcnlTNHVEcGtTRDMxeFFmbWp1SnpCcUh6OGtYcjQ0OXkzRG5PQW9MTDNnUWtVLVRXRWNHMVhtSkI4OUprMTktMUFCNS10OHNNcFM3QjlqLS1sX2VNREtoVlZlcWxpd1pERFlVbUlDY2FTUGlPS3JLWEtR?hl=en-IN&gl=IN&ceid=IN%3Aen
[2025-02-18T14:59:16.751+0000] {logger.py:11} INFO - ====== WebDriver manager ======
[2025-02-18T14:59:16.770+0000] {logger.py:11} INFO - Get LATEST chromedriver version for google-chrome
[2025-02-18T14:59:17.181+0000] {logger.py:11} INFO - About to download new driver from https://chromedriver.storage.googleapis.com/114.0.5735.90/chromedriver_linux64.zip
[2025-02-18T14:59:17.683+0000] {logger.py:11} INFO - Driver downloading response is 200
[2025-02-18T14:59:21.452+0000] {logger.py:11} INFO - Get LATEST chromedriver version for google-chrome
[2025-02-18T14:59:22.072+0000] {logger.py:11} INFO - Get LATEST chromedriver version for google-chrome
[2025-02-18T14:59:22.440+0000] {logger.py:11} INFO - Driver has been saved in cache [/home/***/.wdm/drivers/chromedriver/linux64/114.0.5735.90]
[2025-02-18T14:59:22.460+0000] {logging_mixin.py:190} INFO - Error with Selenium: Message: Service /home/***/.wdm/drivers/chromedriver/linux64/114.0.5735.90/chromedriver unexpectedly exited. Status code was: 127
[2025-02-18T14:59:23.281+0000] {logging_mixin.py:190} INFO - [INFO] Downloaded thumbnail: thumbnail_8.jpg
[2025-02-18T14:59:23.283+0000] {logging_mixin.py:190} INFO - New article added with ID: 8
[2025-02-18T14:59:23.314+0000] {python.py:240} INFO - Done. Returned value was: None
[2025-02-18T14:59:23.330+0000] {taskinstance.py:341} INFO - ::group::Post task execution logs
[2025-02-18T14:59:23.331+0000] {taskinstance.py:353} INFO - Marking task as SUCCESS. dag_id=google_news_scraper, task_id=get_and_parse_articles, run_id=scheduled__2025-02-17T00:00:00+00:00, execution_date=20250217T000000, start_date=20250218T145828, end_date=20250218T145923
[2025-02-18T14:59:23.370+0000] {logging_mixin.py:190} INFO - Task instance in success state
[2025-02-18T14:59:23.371+0000] {logging_mixin.py:190} INFO -  Previous state of the Task instance: running
[2025-02-18T14:59:23.372+0000] {logging_mixin.py:190} INFO - Dag name:google_news_scraper queued_at:2025-02-18 14:58:19.040444+00:00
[2025-02-18T14:59:23.373+0000] {logging_mixin.py:190} INFO - Task hostname:695150105d31 operator:PythonOperator
[2025-02-18T14:59:23.420+0000] {local_task_job_runner.py:266} INFO - Task exited with return code 0
[2025-02-18T14:59:23.448+0000] {taskinstance.py:3901} INFO - 1 downstream tasks scheduled from follow-on schedule check
[2025-02-18T14:59:23.451+0000] {local_task_job_runner.py:245} INFO - ::endgroup::
