[2025-02-19T17:36:11.668+0000] {local_task_job_runner.py:123} INFO - ::group::Pre task execution logs
[2025-02-19T17:36:11.698+0000] {taskinstance.py:2614} INFO - Dependencies all met for dep_context=non-requeueable deps ti=<TaskInstance: google_news_scraper.create_article_table manual__2025-02-19T17:33:23.315521+00:00 [queued]>
[2025-02-19T17:36:11.710+0000] {taskinstance.py:2614} INFO - Dependencies all met for dep_context=requeueable deps ti=<TaskInstance: google_news_scraper.create_article_table manual__2025-02-19T17:33:23.315521+00:00 [queued]>
[2025-02-19T17:36:11.711+0000] {taskinstance.py:2867} INFO - Starting attempt 1 of 1
[2025-02-19T17:36:11.727+0000] {taskinstance.py:2890} INFO - Executing <Task(PostgresOperator): create_article_table> on 2025-02-19 17:33:23.315521+00:00
[2025-02-19T17:36:11.738+0000] {warnings.py:112} WARNING - /home/***/.local/lib/python3.12/site-packages/***/task/task_runner/standard_task_runner.py:70: DeprecationWarning: This process (pid=1001) is multi-threaded, use of fork() may lead to deadlocks in the child.
  pid = os.fork()

[2025-02-19T17:36:11.741+0000] {standard_task_runner.py:72} INFO - Started process 1015 to run task
[2025-02-19T17:36:11.741+0000] {standard_task_runner.py:104} INFO - Running: ['***', 'tasks', 'run', 'google_news_scraper', 'create_article_table', 'manual__2025-02-19T17:33:23.315521+00:00', '--job-id', '45', '--raw', '--subdir', 'DAGS_FOLDER/dag2.py', '--cfg-path', '/tmp/tmpu2pqor9c']
[2025-02-19T17:36:11.743+0000] {standard_task_runner.py:105} INFO - Job 45: Subtask create_article_table
[2025-02-19T17:36:11.801+0000] {task_command.py:467} INFO - Running <TaskInstance: google_news_scraper.create_article_table manual__2025-02-19T17:33:23.315521+00:00 [running]> on host 66d0a4630213
[2025-02-19T17:36:11.898+0000] {taskinstance.py:3134} INFO - Exporting env vars: AIRFLOW_CTX_DAG_OWNER='***' AIRFLOW_CTX_DAG_ID='google_news_scraper' AIRFLOW_CTX_TASK_ID='create_article_table' AIRFLOW_CTX_EXECUTION_DATE='2025-02-19T17:33:23.315521+00:00' AIRFLOW_CTX_TRY_NUMBER='1' AIRFLOW_CTX_DAG_RUN_ID='manual__2025-02-19T17:33:23.315521+00:00'
[2025-02-19T17:36:11.901+0000] {logging_mixin.py:190} INFO - Task instance is in running state
[2025-02-19T17:36:11.901+0000] {logging_mixin.py:190} INFO -  Previous state of the Task instance: queued
[2025-02-19T17:36:11.902+0000] {logging_mixin.py:190} INFO - Current task name:create_article_table state:running start_date:2025-02-19 17:36:11.699554+00:00
[2025-02-19T17:36:11.903+0000] {logging_mixin.py:190} INFO - Dag name:google_news_scraper and current dag run status:running
[2025-02-19T17:36:11.904+0000] {taskinstance.py:732} INFO - ::endgroup::
[2025-02-19T17:36:11.904+0000] {sql.py:295} INFO - Executing: 
        CREATE TABLE IF NOT EXISTS articles (
            id SERIAL PRIMARY KEY,  -- Auto-incrementing ID
            url TEXT UNIQUE NOT NULL, -- URL of the article, ensures uniqueness
            headline TEXT NOT NULL,
            article_date DATE,  -- Date of the article
            scraped_timestamp TIMESTAMP WITH TIME ZONE NOT NULL, -- Timestamp of scraping
            other_metadata JSONB -- Store other metadata as JSON
        );
    
[2025-02-19T17:36:11.913+0000] {base.py:84} INFO - Retrieving connection 'preethi_news_id'
[2025-02-19T17:36:11.923+0000] {base.py:84} INFO - Retrieving connection 'preethi_news_id'
[2025-02-19T17:36:11.924+0000] {sql.py:186} WARNING - This setter is for backward compatibility and should not be used.
Since the introduction of connection property, the providers listed below breaks due to assigning value to self.connection in their __init__ method.
* apache-***-providers-mysql<5.7.1
* apache-***-providers-elasticsearch<5.5.1
* apache-***-providers-postgres<5.13.0
[2025-02-19T17:36:11.928+0000] {taskinstance.py:3313} ERROR - Task failed with exception
Traceback (most recent call last):
  File "/home/airflow/.local/lib/python3.12/site-packages/airflow/models/taskinstance.py", line 768, in _execute_task
    result = _execute_callable(context=context, **execute_callable_kwargs)
             ^^^^^^^^^^^^^^^^^^^^^^^^^^^^^^^^^^^^^^^^^^^^^^^^^^^^^^^^^^^^^
  File "/home/airflow/.local/lib/python3.12/site-packages/airflow/models/taskinstance.py", line 734, in _execute_callable
    return ExecutionCallableRunner(
           ^^^^^^^^^^^^^^^^^^^^^^^^
  File "/home/airflow/.local/lib/python3.12/site-packages/airflow/utils/operator_helpers.py", line 252, in run
    return self.func(*args, **kwargs)
           ^^^^^^^^^^^^^^^^^^^^^^^^^^
  File "/home/airflow/.local/lib/python3.12/site-packages/airflow/models/baseoperator.py", line 424, in wrapper
    return func(self, *args, **kwargs)
           ^^^^^^^^^^^^^^^^^^^^^^^^^^^
  File "/home/airflow/.local/lib/python3.12/site-packages/airflow/providers/common/sql/operators/sql.py", line 301, in execute
    output = hook.run(
             ^^^^^^^^^
  File "/home/airflow/.local/lib/python3.12/site-packages/airflow/providers/common/sql/hooks/sql.py", line 463, in run
    with self._create_autocommit_connection(autocommit) as conn:
         ^^^^^^^^^^^^^^^^^^^^^^^^^^^^^^^^^^^^^^^^^^^^^^
  File "/usr/local/lib/python3.12/contextlib.py", line 137, in __enter__
    return next(self.gen)
           ^^^^^^^^^^^^^^
  File "/home/airflow/.local/lib/python3.12/site-packages/airflow/providers/common/sql/hooks/sql.py", line 576, in _create_autocommit_connection
    with closing(self.get_conn()) as conn:
                 ^^^^^^^^^^^^^^^
  File "/home/airflow/.local/lib/python3.12/site-packages/airflow/providers/postgres/hooks/postgres.py", line 151, in get_conn
    self.conn = psycopg2.connect(**conn_args)
                ^^^^^^^^^^^^^^^^^^^^^^^^^^^^^
  File "/home/airflow/.local/lib/python3.12/site-packages/psycopg2/__init__.py", line 122, in connect
    conn = _connect(dsn, connection_factory=connection_factory, **kwasync)
           ^^^^^^^^^^^^^^^^^^^^^^^^^^^^^^^^^^^^^^^^^^^^^^^^^^^^^^^^^^^^^^^
psycopg2.OperationalError: connection to server at "postgres" (172.30.0.2), port 5432 failed: FATAL:  database "***_db" does not exist

[2025-02-19T17:36:11.939+0000] {logging_mixin.py:190} INFO - Task instance in failure state
[2025-02-19T17:36:11.940+0000] {logging_mixin.py:190} INFO - Task start:2025-02-19 17:36:11.699554+00:00 end:2025-02-19 17:36:11.939420+00:00 duration:0.239866
[2025-02-19T17:36:11.941+0000] {logging_mixin.py:190} INFO - Task:<Task(PostgresOperator): create_article_table> dag:<DAG: google_news_scraper> dagrun:<DagRun google_news_scraper @ 2025-02-19 17:33:23.315521+00:00: manual__2025-02-19T17:33:23.315521+00:00, state:running, queued_at: 2025-02-19 17:33:23.344444+00:00. externally triggered: True>
[2025-02-19T17:36:11.942+0000] {logging_mixin.py:190} INFO - Failure caused by connection to server at "postgres" (172.30.0.2), port 5432 failed: FATAL:  database "***_db" does not exist
[2025-02-19T17:36:11.942+0000] {taskinstance.py:1226} INFO - Marking task as FAILED. dag_id=google_news_scraper, task_id=create_article_table, run_id=manual__2025-02-19T17:33:23.315521+00:00, execution_date=20250219T173323, start_date=20250219T173611, end_date=20250219T173611
[2025-02-19T17:36:11.974+0000] {taskinstance.py:341} INFO - ::group::Post task execution logs
[2025-02-19T17:36:11.974+0000] {standard_task_runner.py:124} ERROR - Failed to execute job 45 for task create_article_table (connection to server at "postgres" (172.30.0.2), port 5432 failed: FATAL:  database "***_db" does not exist
; 1015)
Traceback (most recent call last):
  File "/home/airflow/.local/lib/python3.12/site-packages/airflow/task/task_runner/standard_task_runner.py", line 117, in _start_by_fork
    ret = args.func(args, dag=self.dag)
          ^^^^^^^^^^^^^^^^^^^^^^^^^^^^^
  File "/home/airflow/.local/lib/python3.12/site-packages/airflow/cli/cli_config.py", line 49, in command
    return func(*args, **kwargs)
           ^^^^^^^^^^^^^^^^^^^^^
  File "/home/airflow/.local/lib/python3.12/site-packages/airflow/utils/cli.py", line 116, in wrapper
    return f(*args, **kwargs)
           ^^^^^^^^^^^^^^^^^^
  File "/home/airflow/.local/lib/python3.12/site-packages/airflow/cli/commands/task_command.py", line 483, in task_run
    task_return_code = _run_task_by_selected_method(args, _dag, ti)
                       ^^^^^^^^^^^^^^^^^^^^^^^^^^^^^^^^^^^^^^^^^^^^
  File "/home/airflow/.local/lib/python3.12/site-packages/airflow/cli/commands/task_command.py", line 256, in _run_task_by_selected_method
    return _run_raw_task(args, ti)
           ^^^^^^^^^^^^^^^^^^^^^^^
  File "/home/airflow/.local/lib/python3.12/site-packages/airflow/cli/commands/task_command.py", line 341, in _run_raw_task
    return ti._run_raw_task(
           ^^^^^^^^^^^^^^^^^
  File "/home/airflow/.local/lib/python3.12/site-packages/airflow/utils/session.py", line 97, in wrapper
    return func(*args, session=session, **kwargs)
           ^^^^^^^^^^^^^^^^^^^^^^^^^^^^^^^^^^^^^^
  File "/home/airflow/.local/lib/python3.12/site-packages/airflow/models/taskinstance.py", line 3006, in _run_raw_task
    return _run_raw_task(
           ^^^^^^^^^^^^^^
  File "/home/airflow/.local/lib/python3.12/site-packages/airflow/models/taskinstance.py", line 274, in _run_raw_task
    TaskInstance._execute_task_with_callbacks(
  File "/home/airflow/.local/lib/python3.12/site-packages/airflow/models/taskinstance.py", line 3161, in _execute_task_with_callbacks
    result = self._execute_task(context, task_orig)
             ^^^^^^^^^^^^^^^^^^^^^^^^^^^^^^^^^^^^^^
  File "/home/airflow/.local/lib/python3.12/site-packages/airflow/models/taskinstance.py", line 3185, in _execute_task
    return _execute_task(self, context, task_orig)
           ^^^^^^^^^^^^^^^^^^^^^^^^^^^^^^^^^^^^^^^
  File "/home/airflow/.local/lib/python3.12/site-packages/airflow/models/taskinstance.py", line 768, in _execute_task
    result = _execute_callable(context=context, **execute_callable_kwargs)
             ^^^^^^^^^^^^^^^^^^^^^^^^^^^^^^^^^^^^^^^^^^^^^^^^^^^^^^^^^^^^^
  File "/home/airflow/.local/lib/python3.12/site-packages/airflow/models/taskinstance.py", line 734, in _execute_callable
    return ExecutionCallableRunner(
           ^^^^^^^^^^^^^^^^^^^^^^^^
  File "/home/airflow/.local/lib/python3.12/site-packages/airflow/utils/operator_helpers.py", line 252, in run
    return self.func(*args, **kwargs)
           ^^^^^^^^^^^^^^^^^^^^^^^^^^
  File "/home/airflow/.local/lib/python3.12/site-packages/airflow/models/baseoperator.py", line 424, in wrapper
    return func(self, *args, **kwargs)
           ^^^^^^^^^^^^^^^^^^^^^^^^^^^
  File "/home/airflow/.local/lib/python3.12/site-packages/airflow/providers/common/sql/operators/sql.py", line 301, in execute
    output = hook.run(
             ^^^^^^^^^
  File "/home/airflow/.local/lib/python3.12/site-packages/airflow/providers/common/sql/hooks/sql.py", line 463, in run
    with self._create_autocommit_connection(autocommit) as conn:
         ^^^^^^^^^^^^^^^^^^^^^^^^^^^^^^^^^^^^^^^^^^^^^^
  File "/usr/local/lib/python3.12/contextlib.py", line 137, in __enter__
    return next(self.gen)
           ^^^^^^^^^^^^^^
  File "/home/airflow/.local/lib/python3.12/site-packages/airflow/providers/common/sql/hooks/sql.py", line 576, in _create_autocommit_connection
    with closing(self.get_conn()) as conn:
                 ^^^^^^^^^^^^^^^
  File "/home/airflow/.local/lib/python3.12/site-packages/airflow/providers/postgres/hooks/postgres.py", line 151, in get_conn
    self.conn = psycopg2.connect(**conn_args)
                ^^^^^^^^^^^^^^^^^^^^^^^^^^^^^
  File "/home/airflow/.local/lib/python3.12/site-packages/psycopg2/__init__.py", line 122, in connect
    conn = _connect(dsn, connection_factory=connection_factory, **kwasync)
           ^^^^^^^^^^^^^^^^^^^^^^^^^^^^^^^^^^^^^^^^^^^^^^^^^^^^^^^^^^^^^^^
psycopg2.OperationalError: connection to server at "postgres" (172.30.0.2), port 5432 failed: FATAL:  database "***_db" does not exist

[2025-02-19T17:36:12.001+0000] {local_task_job_runner.py:266} INFO - Task exited with return code 1
[2025-02-19T17:36:12.028+0000] {taskinstance.py:3901} INFO - 0 downstream tasks scheduled from follow-on schedule check
[2025-02-19T17:36:12.036+0000] {local_task_job_runner.py:245} INFO - ::endgroup::
