[2025-02-16T13:43:31.995+0000] {local_task_job_runner.py:123} INFO - ::group::Pre task execution logs
[2025-02-16T13:43:32.006+0000] {taskinstance.py:2614} INFO - Dependencies all met for dep_context=non-requeueable deps ti=<TaskInstance: google_news_scraper.fetch_news manual__2025-02-16T13:38:25.718022+00:00 [queued]>
[2025-02-16T13:43:32.011+0000] {taskinstance.py:2614} INFO - Dependencies all met for dep_context=requeueable deps ti=<TaskInstance: google_news_scraper.fetch_news manual__2025-02-16T13:38:25.718022+00:00 [queued]>
[2025-02-16T13:43:32.012+0000] {taskinstance.py:2867} INFO - Starting attempt 2 of 2
[2025-02-16T13:43:32.023+0000] {taskinstance.py:2890} INFO - Executing <Task(PythonOperator): fetch_news> on 2025-02-16 13:38:25.718022+00:00
[2025-02-16T13:43:32.033+0000] {warnings.py:112} WARNING - /home/***/.local/lib/python3.12/site-packages/***/task/task_runner/standard_task_runner.py:70: DeprecationWarning: This process (pid=315) is multi-threaded, use of fork() may lead to deadlocks in the child.
  pid = os.fork()

[2025-02-16T13:43:32.036+0000] {standard_task_runner.py:104} INFO - Running: ['***', 'tasks', 'run', 'google_news_scraper', 'fetch_news', 'manual__2025-02-16T13:38:25.718022+00:00', '--job-id', '20', '--raw', '--subdir', 'DAGS_FOLDER/google_news_dag.py', '--cfg-path', '/tmp/tmp1x104sk9']
[2025-02-16T13:43:32.038+0000] {standard_task_runner.py:72} INFO - Started process 318 to run task
[2025-02-16T13:43:32.038+0000] {standard_task_runner.py:105} INFO - Job 20: Subtask fetch_news
[2025-02-16T13:43:32.087+0000] {task_command.py:467} INFO - Running <TaskInstance: google_news_scraper.fetch_news manual__2025-02-16T13:38:25.718022+00:00 [running]> on host 30fd5a79001b
[2025-02-16T13:43:32.158+0000] {taskinstance.py:3134} INFO - Exporting env vars: AIRFLOW_CTX_DAG_OWNER='***' AIRFLOW_CTX_DAG_ID='google_news_scraper' AIRFLOW_CTX_TASK_ID='fetch_news' AIRFLOW_CTX_EXECUTION_DATE='2025-02-16T13:38:25.718022+00:00' AIRFLOW_CTX_TRY_NUMBER='2' AIRFLOW_CTX_DAG_RUN_ID='manual__2025-02-16T13:38:25.718022+00:00'
[2025-02-16T13:43:32.160+0000] {logging_mixin.py:190} INFO - Task instance is in running state
[2025-02-16T13:43:32.161+0000] {logging_mixin.py:190} INFO -  Previous state of the Task instance: queued
[2025-02-16T13:43:32.161+0000] {logging_mixin.py:190} INFO - Current task name:fetch_news state:running start_date:2025-02-16 13:43:32.006845+00:00
[2025-02-16T13:43:32.162+0000] {logging_mixin.py:190} INFO - Dag name:google_news_scraper and current dag run status:running
[2025-02-16T13:43:32.162+0000] {taskinstance.py:732} INFO - ::endgroup::
[2025-02-16T13:43:32.164+0000] {logging_mixin.py:190} WARNING - usage: *** [-h] [--config CONFIG]
[2025-02-16T13:43:32.164+0000] {logging_mixin.py:190} WARNING - ***: error: unrecognized arguments: celery worker
[2025-02-16T13:43:32.165+0000] {taskinstance.py:3315} ERROR - Task failed due to SystemExit(2)
[2025-02-16T13:43:32.171+0000] {logging_mixin.py:190} INFO - Task instance in failure state
[2025-02-16T13:43:32.172+0000] {logging_mixin.py:190} INFO - Task start:2025-02-16 13:43:32.006845+00:00 end:2025-02-16 13:43:32.171046+00:00 duration:0.164201
[2025-02-16T13:43:32.172+0000] {logging_mixin.py:190} INFO - Task:<Task(PythonOperator): fetch_news> dag:<DAG: google_news_scraper> dagrun:<DagRun google_news_scraper @ 2025-02-16 13:38:25.718022+00:00: manual__2025-02-16T13:38:25.718022+00:00, state:running, queued_at: 2025-02-16 13:38:25.750405+00:00. externally triggered: True>
[2025-02-16T13:43:32.173+0000] {logging_mixin.py:190} INFO - Failure caused by Task failed due to SystemExit(2)
[2025-02-16T13:43:32.173+0000] {taskinstance.py:1226} INFO - Marking task as FAILED. dag_id=google_news_scraper, task_id=fetch_news, run_id=manual__2025-02-16T13:38:25.718022+00:00, execution_date=20250216T133825, start_date=20250216T134332, end_date=20250216T134332
[2025-02-16T13:43:32.200+0000] {taskinstance.py:341} INFO - ::group::Post task execution logs
[2025-02-16T13:43:32.201+0000] {standard_task_runner.py:124} ERROR - Failed to execute job 20 for task fetch_news (Task failed due to SystemExit(2); 318)
Traceback (most recent call last):
  File "/home/airflow/.local/lib/python3.12/site-packages/airflow/models/taskinstance.py", line 274, in _run_raw_task
    TaskInstance._execute_task_with_callbacks(
  File "/home/airflow/.local/lib/python3.12/site-packages/airflow/models/taskinstance.py", line 3161, in _execute_task_with_callbacks
    result = self._execute_task(context, task_orig)
             ^^^^^^^^^^^^^^^^^^^^^^^^^^^^^^^^^^^^^^
  File "/home/airflow/.local/lib/python3.12/site-packages/airflow/models/taskinstance.py", line 3185, in _execute_task
    return _execute_task(self, context, task_orig)
           ^^^^^^^^^^^^^^^^^^^^^^^^^^^^^^^^^^^^^^^
  File "/home/airflow/.local/lib/python3.12/site-packages/airflow/models/taskinstance.py", line 768, in _execute_task
    result = _execute_callable(context=context, **execute_callable_kwargs)
             ^^^^^^^^^^^^^^^^^^^^^^^^^^^^^^^^^^^^^^^^^^^^^^^^^^^^^^^^^^^^^
  File "/home/airflow/.local/lib/python3.12/site-packages/airflow/models/taskinstance.py", line 734, in _execute_callable
    return ExecutionCallableRunner(
           ^^^^^^^^^^^^^^^^^^^^^^^^
  File "/home/airflow/.local/lib/python3.12/site-packages/airflow/utils/operator_helpers.py", line 252, in run
    return self.func(*args, **kwargs)
           ^^^^^^^^^^^^^^^^^^^^^^^^^^
  File "/home/airflow/.local/lib/python3.12/site-packages/airflow/models/baseoperator.py", line 424, in wrapper
    return func(self, *args, **kwargs)
           ^^^^^^^^^^^^^^^^^^^^^^^^^^^
  File "/home/airflow/.local/lib/python3.12/site-packages/airflow/operators/python.py", line 238, in execute
    return_value = self.execute_callable()
                   ^^^^^^^^^^^^^^^^^^^^^^^
  File "/home/airflow/.local/lib/python3.12/site-packages/airflow/operators/python.py", line 256, in execute_callable
    return runner.run(*self.op_args, **self.op_kwargs)
           ^^^^^^^^^^^^^^^^^^^^^^^^^^^^^^^^^^^^^^^^^^^
  File "/home/airflow/.local/lib/python3.12/site-packages/airflow/utils/operator_helpers.py", line 252, in run
    return self.func(*args, **kwargs)
           ^^^^^^^^^^^^^^^^^^^^^^^^^^
  File "/opt/airflow/dags/google_news_dag.py", line 36, in fetch_news_data
    args = parser.parse_args()
           ^^^^^^^^^^^^^^^^^^^
  File "/usr/local/lib/python3.12/argparse.py", line 1908, in parse_args
    self.error(msg)
  File "/usr/local/lib/python3.12/argparse.py", line 2650, in error
    self.exit(2, _('%(prog)s: error: %(message)s\n') % args)
  File "/usr/local/lib/python3.12/argparse.py", line 2637, in exit
    _sys.exit(status)
  File "/home/airflow/.local/lib/python3.12/site-packages/billiard/pool.py", line 283, in exit
    return _exit(status)
           ^^^^^^^^^^^^^
SystemExit: 2

During handling of the above exception, another exception occurred:

Traceback (most recent call last):
  File "/home/airflow/.local/lib/python3.12/site-packages/airflow/task/task_runner/standard_task_runner.py", line 117, in _start_by_fork
    ret = args.func(args, dag=self.dag)
          ^^^^^^^^^^^^^^^^^^^^^^^^^^^^^
  File "/home/airflow/.local/lib/python3.12/site-packages/airflow/cli/cli_config.py", line 49, in command
    return func(*args, **kwargs)
           ^^^^^^^^^^^^^^^^^^^^^
  File "/home/airflow/.local/lib/python3.12/site-packages/airflow/utils/cli.py", line 116, in wrapper
    return f(*args, **kwargs)
           ^^^^^^^^^^^^^^^^^^
  File "/home/airflow/.local/lib/python3.12/site-packages/airflow/cli/commands/task_command.py", line 483, in task_run
    task_return_code = _run_task_by_selected_method(args, _dag, ti)
                       ^^^^^^^^^^^^^^^^^^^^^^^^^^^^^^^^^^^^^^^^^^^^
  File "/home/airflow/.local/lib/python3.12/site-packages/airflow/cli/commands/task_command.py", line 256, in _run_task_by_selected_method
    return _run_raw_task(args, ti)
           ^^^^^^^^^^^^^^^^^^^^^^^
  File "/home/airflow/.local/lib/python3.12/site-packages/airflow/cli/commands/task_command.py", line 341, in _run_raw_task
    return ti._run_raw_task(
           ^^^^^^^^^^^^^^^^^
  File "/home/airflow/.local/lib/python3.12/site-packages/airflow/utils/session.py", line 97, in wrapper
    return func(*args, session=session, **kwargs)
           ^^^^^^^^^^^^^^^^^^^^^^^^^^^^^^^^^^^^^^
  File "/home/airflow/.local/lib/python3.12/site-packages/airflow/models/taskinstance.py", line 3006, in _run_raw_task
    return _run_raw_task(
           ^^^^^^^^^^^^^^
  File "/home/airflow/.local/lib/python3.12/site-packages/airflow/models/taskinstance.py", line 335, in _run_raw_task
    raise AirflowException(msg)
airflow.exceptions.AirflowException: Task failed due to SystemExit(2)
[2025-02-16T13:43:32.254+0000] {local_task_job_runner.py:266} INFO - Task exited with return code 1
[2025-02-16T13:43:32.282+0000] {taskinstance.py:3901} INFO - 0 downstream tasks scheduled from follow-on schedule check
[2025-02-16T13:43:32.286+0000] {local_task_job_runner.py:245} INFO - ::endgroup::
