[2025-02-16T10:49:09.027+0000] {local_task_job_runner.py:123} INFO - ::group::Pre task execution logs
[2025-02-16T10:49:09.049+0000] {taskinstance.py:2614} INFO - Dependencies all met for dep_context=non-requeueable deps ti=<TaskInstance: google_news_scraper.get_and_parse_articles scheduled__2025-02-15T00:00:00+00:00 [queued]>
[2025-02-16T10:49:09.061+0000] {taskinstance.py:2614} INFO - Dependencies all met for dep_context=requeueable deps ti=<TaskInstance: google_news_scraper.get_and_parse_articles scheduled__2025-02-15T00:00:00+00:00 [queued]>
[2025-02-16T10:49:09.062+0000] {taskinstance.py:2867} INFO - Starting attempt 1 of 4
[2025-02-16T10:49:09.077+0000] {taskinstance.py:2890} INFO - Executing <Task(PythonOperator): get_and_parse_articles> on 2025-02-15 00:00:00+00:00
[2025-02-16T10:49:09.088+0000] {warnings.py:112} WARNING - /home/***/.local/lib/python3.12/site-packages/***/task/task_runner/standard_task_runner.py:70: DeprecationWarning: This process (pid=160) is multi-threaded, use of fork() may lead to deadlocks in the child.
  pid = os.fork()

[2025-02-16T10:49:09.090+0000] {standard_task_runner.py:72} INFO - Started process 192 to run task
[2025-02-16T10:49:09.091+0000] {standard_task_runner.py:104} INFO - Running: ['***', 'tasks', 'run', 'google_news_scraper', 'get_and_parse_articles', 'scheduled__2025-02-15T00:00:00+00:00', '--job-id', '9', '--raw', '--subdir', 'DAGS_FOLDER/dag1.py', '--cfg-path', '/tmp/tmpk7425myi']
[2025-02-16T10:49:09.092+0000] {standard_task_runner.py:105} INFO - Job 9: Subtask get_and_parse_articles
[2025-02-16T10:49:09.148+0000] {task_command.py:467} INFO - Running <TaskInstance: google_news_scraper.get_and_parse_articles scheduled__2025-02-15T00:00:00+00:00 [running]> on host 303d3deb3770
[2025-02-16T10:49:09.231+0000] {taskinstance.py:3134} INFO - Exporting env vars: AIRFLOW_CTX_DAG_OWNER='***' AIRFLOW_CTX_DAG_ID='google_news_scraper' AIRFLOW_CTX_TASK_ID='get_and_parse_articles' AIRFLOW_CTX_EXECUTION_DATE='2025-02-15T00:00:00+00:00' AIRFLOW_CTX_TRY_NUMBER='1' AIRFLOW_CTX_DAG_RUN_ID='scheduled__2025-02-15T00:00:00+00:00'
[2025-02-16T10:49:09.233+0000] {logging_mixin.py:190} INFO - Task instance is in running state
[2025-02-16T10:49:09.234+0000] {logging_mixin.py:190} INFO -  Previous state of the Task instance: queued
[2025-02-16T10:49:09.234+0000] {logging_mixin.py:190} INFO - Current task name:get_and_parse_articles state:running start_date:2025-02-16 10:49:09.049758+00:00
[2025-02-16T10:49:09.235+0000] {logging_mixin.py:190} INFO - Dag name:google_news_scraper and current dag run status:running
[2025-02-16T10:49:09.236+0000] {taskinstance.py:732} INFO - ::endgroup::
[2025-02-16T10:49:09.244+0000] {dag1.py:12} INFO - Starting task: Get Google News Homepage
[2025-02-16T10:49:11.460+0000] {dag1.py:16} INFO - Completed task: Get Google News Homepage
[2025-02-16T10:49:11.461+0000] {dag1.py:12} INFO - Starting task: Parse Google News Articles
[2025-02-16T10:49:11.485+0000] {warnings.py:112} WARNING - /home/***/.local/lib/python3.12/site-packages/pymongo/_csot.py:119: UserWarning: MongoClient opened before fork. May not be entirely fork-safe, proceed with caution. See PyMongo's documentation for details: https://www.mongodb.com/docs/languages/python/pymongo-driver/current/faq/#is-pymongo-fork-safe-
  return func(self, *args, **kwargs)

[2025-02-16T10:49:41.081+0000] {dag1.py:20} ERROR - Error in task Get and Parse Articles: localhost:27017: [Errno 111] Connection refused (configured timeouts: socketTimeoutMS: 20000.0ms, connectTimeoutMS: 20000.0ms), Timeout: 30s, Topology Description: <TopologyDescription id: 67b1c2a3feba17ec89b72109, topology_type: Unknown, servers: [<ServerDescription ('localhost', 27017) server_type: Unknown, rtt: None, error=AutoReconnect('localhost:27017: [Errno 111] Connection refused (configured timeouts: socketTimeoutMS: 20000.0ms, connectTimeoutMS: 20000.0ms)')>]>
[2025-02-16T10:49:41.088+0000] {dag1.py:21} ERROR - Traceback: Traceback (most recent call last):
  File "/opt/***/dags/dag1.py", line 51, in get_and_parse_articles
    articles = parse_google_news(html)
               ^^^^^^^^^^^^^^^^^^^^^^^
  File "/opt/***/dags/google_news_scraper.py", line 213, in parse_google_news
    article_counter = get_next_article_id()  # Initialize counter from the last ID in the DB
                      ^^^^^^^^^^^^^^^^^^^^^
  File "/opt/***/dags/google_news_scraper.py", line 172, in get_next_article_id
    last_article = collection.find_one(sort=[("article_id", -1)])
                   ^^^^^^^^^^^^^^^^^^^^^^^^^^^^^^^^^^^^^^^^^^^^^^
  File "/home/***/.local/lib/python3.12/site-packages/pymongo/synchronous/collection.py", line 1755, in find_one
    for result in cursor.limit(-1):
                  ^^^^^^^^^^^^^^^^
  File "/home/***/.local/lib/python3.12/site-packages/pymongo/synchronous/cursor.py", line 1281, in __next__
    return self.next()
           ^^^^^^^^^^^
  File "/home/***/.local/lib/python3.12/site-packages/pymongo/synchronous/cursor.py", line 1257, in next
    if len(self._data) or self._refresh():
                          ^^^^^^^^^^^^^^^
  File "/home/***/.local/lib/python3.12/site-packages/pymongo/synchronous/cursor.py", line 1205, in _refresh
    self._send_message(q)
  File "/home/***/.local/lib/python3.12/site-packages/pymongo/synchronous/cursor.py", line 1100, in _send_message
    response = client._run_operation(
               ^^^^^^^^^^^^^^^^^^^^^^
  File "/home/***/.local/lib/python3.12/site-packages/pymongo/_csot.py", line 119, in csot_wrapper
    return func(self, *args, **kwargs)
           ^^^^^^^^^^^^^^^^^^^^^^^^^^^
  File "/home/***/.local/lib/python3.12/site-packages/pymongo/synchronous/mongo_client.py", line 1752, in _run_operation
    return self._retryable_read(
           ^^^^^^^^^^^^^^^^^^^^^
  File "/home/***/.local/lib/python3.12/site-packages/pymongo/synchronous/mongo_client.py", line 1861, in _retryable_read
    return self._retry_internal(
           ^^^^^^^^^^^^^^^^^^^^^
  File "/home/***/.local/lib/python3.12/site-packages/pymongo/_csot.py", line 119, in csot_wrapper
    return func(self, *args, **kwargs)
           ^^^^^^^^^^^^^^^^^^^^^^^^^^^
  File "/home/***/.local/lib/python3.12/site-packages/pymongo/synchronous/mongo_client.py", line 1828, in _retry_internal
    ).run()
      ^^^^^
  File "/home/***/.local/lib/python3.12/site-packages/pymongo/synchronous/mongo_client.py", line 2565, in run
    return self._read() if self._is_read else self._write()
           ^^^^^^^^^^^^
  File "/home/***/.local/lib/python3.12/site-packages/pymongo/synchronous/mongo_client.py", line 2700, in _read
    self._server = self._get_server()
                   ^^^^^^^^^^^^^^^^^^
  File "/home/***/.local/lib/python3.12/site-packages/pymongo/synchronous/mongo_client.py", line 2656, in _get_server
    return self._client._select_server(
           ^^^^^^^^^^^^^^^^^^^^^^^^^^^^
  File "/home/***/.local/lib/python3.12/site-packages/pymongo/synchronous/mongo_client.py", line 1647, in _select_server
    server = topology.select_server(
             ^^^^^^^^^^^^^^^^^^^^^^^
  File "/home/***/.local/lib/python3.12/site-packages/pymongo/synchronous/topology.py", line 402, in select_server
    server = self._select_server(
             ^^^^^^^^^^^^^^^^^^^^
  File "/home/***/.local/lib/python3.12/site-packages/pymongo/synchronous/topology.py", line 380, in _select_server
    servers = self.select_servers(
              ^^^^^^^^^^^^^^^^^^^^
  File "/home/***/.local/lib/python3.12/site-packages/pymongo/synchronous/topology.py", line 287, in select_servers
    server_descriptions = self._select_servers_loop(
                          ^^^^^^^^^^^^^^^^^^^^^^^^^^
  File "/home/***/.local/lib/python3.12/site-packages/pymongo/synchronous/topology.py", line 337, in _select_servers_loop
    raise ServerSelectionTimeoutError(
pymongo.errors.ServerSelectionTimeoutError: localhost:27017: [Errno 111] Connection refused (configured timeouts: socketTimeoutMS: 20000.0ms, connectTimeoutMS: 20000.0ms), Timeout: 30s, Topology Description: <TopologyDescription id: 67b1c2a3feba17ec89b72109, topology_type: Unknown, servers: [<ServerDescription ('localhost', 27017) server_type: Unknown, rtt: None, error=AutoReconnect('localhost:27017: [Errno 111] Connection refused (configured timeouts: socketTimeoutMS: 20000.0ms, connectTimeoutMS: 20000.0ms)')>]>

[2025-02-16T10:49:41.089+0000] {taskinstance.py:3313} ERROR - Task failed with exception
Traceback (most recent call last):
  File "/home/airflow/.local/lib/python3.12/site-packages/airflow/models/taskinstance.py", line 768, in _execute_task
    result = _execute_callable(context=context, **execute_callable_kwargs)
             ^^^^^^^^^^^^^^^^^^^^^^^^^^^^^^^^^^^^^^^^^^^^^^^^^^^^^^^^^^^^^
  File "/home/airflow/.local/lib/python3.12/site-packages/airflow/models/taskinstance.py", line 734, in _execute_callable
    return ExecutionCallableRunner(
           ^^^^^^^^^^^^^^^^^^^^^^^^
  File "/home/airflow/.local/lib/python3.12/site-packages/airflow/utils/operator_helpers.py", line 252, in run
    return self.func(*args, **kwargs)
           ^^^^^^^^^^^^^^^^^^^^^^^^^^
  File "/home/airflow/.local/lib/python3.12/site-packages/airflow/models/baseoperator.py", line 424, in wrapper
    return func(self, *args, **kwargs)
           ^^^^^^^^^^^^^^^^^^^^^^^^^^^
  File "/home/airflow/.local/lib/python3.12/site-packages/airflow/operators/python.py", line 238, in execute
    return_value = self.execute_callable()
                   ^^^^^^^^^^^^^^^^^^^^^^^
  File "/home/airflow/.local/lib/python3.12/site-packages/airflow/operators/python.py", line 256, in execute_callable
    return runner.run(*self.op_args, **self.op_kwargs)
           ^^^^^^^^^^^^^^^^^^^^^^^^^^^^^^^^^^^^^^^^^^^
  File "/home/airflow/.local/lib/python3.12/site-packages/airflow/utils/operator_helpers.py", line 252, in run
    return self.func(*args, **kwargs)
           ^^^^^^^^^^^^^^^^^^^^^^^^^^
  File "/opt/airflow/dags/dag1.py", line 51, in get_and_parse_articles
    articles = parse_google_news(html)
               ^^^^^^^^^^^^^^^^^^^^^^^
  File "/opt/airflow/dags/google_news_scraper.py", line 213, in parse_google_news
    article_counter = get_next_article_id()  # Initialize counter from the last ID in the DB
                      ^^^^^^^^^^^^^^^^^^^^^
  File "/opt/airflow/dags/google_news_scraper.py", line 172, in get_next_article_id
    last_article = collection.find_one(sort=[("article_id", -1)])
                   ^^^^^^^^^^^^^^^^^^^^^^^^^^^^^^^^^^^^^^^^^^^^^^
  File "/home/airflow/.local/lib/python3.12/site-packages/pymongo/synchronous/collection.py", line 1755, in find_one
    for result in cursor.limit(-1):
                  ^^^^^^^^^^^^^^^^
  File "/home/airflow/.local/lib/python3.12/site-packages/pymongo/synchronous/cursor.py", line 1281, in __next__
    return self.next()
           ^^^^^^^^^^^
  File "/home/airflow/.local/lib/python3.12/site-packages/pymongo/synchronous/cursor.py", line 1257, in next
    if len(self._data) or self._refresh():
                          ^^^^^^^^^^^^^^^
  File "/home/airflow/.local/lib/python3.12/site-packages/pymongo/synchronous/cursor.py", line 1205, in _refresh
    self._send_message(q)
  File "/home/airflow/.local/lib/python3.12/site-packages/pymongo/synchronous/cursor.py", line 1100, in _send_message
    response = client._run_operation(
               ^^^^^^^^^^^^^^^^^^^^^^
  File "/home/airflow/.local/lib/python3.12/site-packages/pymongo/_csot.py", line 119, in csot_wrapper
    return func(self, *args, **kwargs)
           ^^^^^^^^^^^^^^^^^^^^^^^^^^^
  File "/home/airflow/.local/lib/python3.12/site-packages/pymongo/synchronous/mongo_client.py", line 1752, in _run_operation
    return self._retryable_read(
           ^^^^^^^^^^^^^^^^^^^^^
  File "/home/airflow/.local/lib/python3.12/site-packages/pymongo/synchronous/mongo_client.py", line 1861, in _retryable_read
    return self._retry_internal(
           ^^^^^^^^^^^^^^^^^^^^^
  File "/home/airflow/.local/lib/python3.12/site-packages/pymongo/_csot.py", line 119, in csot_wrapper
    return func(self, *args, **kwargs)
           ^^^^^^^^^^^^^^^^^^^^^^^^^^^
  File "/home/airflow/.local/lib/python3.12/site-packages/pymongo/synchronous/mongo_client.py", line 1828, in _retry_internal
    ).run()
      ^^^^^
  File "/home/airflow/.local/lib/python3.12/site-packages/pymongo/synchronous/mongo_client.py", line 2565, in run
    return self._read() if self._is_read else self._write()
           ^^^^^^^^^^^^
  File "/home/airflow/.local/lib/python3.12/site-packages/pymongo/synchronous/mongo_client.py", line 2700, in _read
    self._server = self._get_server()
                   ^^^^^^^^^^^^^^^^^^
  File "/home/airflow/.local/lib/python3.12/site-packages/pymongo/synchronous/mongo_client.py", line 2656, in _get_server
    return self._client._select_server(
           ^^^^^^^^^^^^^^^^^^^^^^^^^^^^
  File "/home/airflow/.local/lib/python3.12/site-packages/pymongo/synchronous/mongo_client.py", line 1647, in _select_server
    server = topology.select_server(
             ^^^^^^^^^^^^^^^^^^^^^^^
  File "/home/airflow/.local/lib/python3.12/site-packages/pymongo/synchronous/topology.py", line 402, in select_server
    server = self._select_server(
             ^^^^^^^^^^^^^^^^^^^^
  File "/home/airflow/.local/lib/python3.12/site-packages/pymongo/synchronous/topology.py", line 380, in _select_server
    servers = self.select_servers(
              ^^^^^^^^^^^^^^^^^^^^
  File "/home/airflow/.local/lib/python3.12/site-packages/pymongo/synchronous/topology.py", line 287, in select_servers
    server_descriptions = self._select_servers_loop(
                          ^^^^^^^^^^^^^^^^^^^^^^^^^^
  File "/home/airflow/.local/lib/python3.12/site-packages/pymongo/synchronous/topology.py", line 337, in _select_servers_loop
    raise ServerSelectionTimeoutError(
pymongo.errors.ServerSelectionTimeoutError: localhost:27017: [Errno 111] Connection refused (configured timeouts: socketTimeoutMS: 20000.0ms, connectTimeoutMS: 20000.0ms), Timeout: 30s, Topology Description: <TopologyDescription id: 67b1c2a3feba17ec89b72109, topology_type: Unknown, servers: [<ServerDescription ('localhost', 27017) server_type: Unknown, rtt: None, error=AutoReconnect('localhost:27017: [Errno 111] Connection refused (configured timeouts: socketTimeoutMS: 20000.0ms, connectTimeoutMS: 20000.0ms)')>]>
[2025-02-16T10:49:41.109+0000] {logging_mixin.py:190} INFO - Task instance in failure state
[2025-02-16T10:49:41.110+0000] {logging_mixin.py:190} INFO - Task start:2025-02-16 10:49:09.049758+00:00 end:2025-02-16 10:49:41.108947+00:00 duration:32.059189
[2025-02-16T10:49:41.111+0000] {logging_mixin.py:190} INFO - Task:<Task(PythonOperator): get_and_parse_articles> dag:<DAG: google_news_scraper> dagrun:<DagRun google_news_scraper @ 2025-02-15 00:00:00+00:00: scheduled__2025-02-15T00:00:00+00:00, state:running, queued_at: 2025-02-16 10:49:00.755552+00:00. externally triggered: False>
[2025-02-16T10:49:41.113+0000] {logging_mixin.py:190} INFO - Failure caused by localhost:27017: [Errno 111] Connection refused (configured timeouts: socketTimeoutMS: 20000.0ms, connectTimeoutMS: 20000.0ms), Timeout: 30s, Topology Description: <TopologyDescription id: 67b1c2a3feba17ec89b72109, topology_type: Unknown, servers: [<ServerDescription ('localhost', 27017) server_type: Unknown, rtt: None, error=AutoReconnect('localhost:27017: [Errno 111] Connection refused (configured timeouts: socketTimeoutMS: 20000.0ms, connectTimeoutMS: 20000.0ms)')>]>
[2025-02-16T10:49:41.114+0000] {taskinstance.py:1226} INFO - Marking task as UP_FOR_RETRY. dag_id=google_news_scraper, task_id=get_and_parse_articles, run_id=scheduled__2025-02-15T00:00:00+00:00, execution_date=20250215T000000, start_date=20250216T104909, end_date=20250216T104941
[2025-02-16T10:49:41.149+0000] {taskinstance.py:341} INFO - ::group::Post task execution logs
[2025-02-16T10:49:41.150+0000] {standard_task_runner.py:124} ERROR - Failed to execute job 9 for task get_and_parse_articles (localhost:27017: [Errno 111] Connection refused (configured timeouts: socketTimeoutMS: 20000.0ms, connectTimeoutMS: 20000.0ms), Timeout: 30s, Topology Description: <TopologyDescription id: 67b1c2a3feba17ec89b72109, topology_type: Unknown, servers: [<ServerDescription ('localhost', 27017) server_type: Unknown, rtt: None, error=AutoReconnect('localhost:27017: [Errno 111] Connection refused (configured timeouts: socketTimeoutMS: 20000.0ms, connectTimeoutMS: 20000.0ms)')>]>; 192)
Traceback (most recent call last):
  File "/home/airflow/.local/lib/python3.12/site-packages/airflow/task/task_runner/standard_task_runner.py", line 117, in _start_by_fork
    ret = args.func(args, dag=self.dag)
          ^^^^^^^^^^^^^^^^^^^^^^^^^^^^^
  File "/home/airflow/.local/lib/python3.12/site-packages/airflow/cli/cli_config.py", line 49, in command
    return func(*args, **kwargs)
           ^^^^^^^^^^^^^^^^^^^^^
  File "/home/airflow/.local/lib/python3.12/site-packages/airflow/utils/cli.py", line 116, in wrapper
    return f(*args, **kwargs)
           ^^^^^^^^^^^^^^^^^^
  File "/home/airflow/.local/lib/python3.12/site-packages/airflow/cli/commands/task_command.py", line 483, in task_run
    task_return_code = _run_task_by_selected_method(args, _dag, ti)
                       ^^^^^^^^^^^^^^^^^^^^^^^^^^^^^^^^^^^^^^^^^^^^
  File "/home/airflow/.local/lib/python3.12/site-packages/airflow/cli/commands/task_command.py", line 256, in _run_task_by_selected_method
    return _run_raw_task(args, ti)
           ^^^^^^^^^^^^^^^^^^^^^^^
  File "/home/airflow/.local/lib/python3.12/site-packages/airflow/cli/commands/task_command.py", line 341, in _run_raw_task
    return ti._run_raw_task(
           ^^^^^^^^^^^^^^^^^
  File "/home/airflow/.local/lib/python3.12/site-packages/airflow/utils/session.py", line 97, in wrapper
    return func(*args, session=session, **kwargs)
           ^^^^^^^^^^^^^^^^^^^^^^^^^^^^^^^^^^^^^^
  File "/home/airflow/.local/lib/python3.12/site-packages/airflow/models/taskinstance.py", line 3006, in _run_raw_task
    return _run_raw_task(
           ^^^^^^^^^^^^^^
  File "/home/airflow/.local/lib/python3.12/site-packages/airflow/models/taskinstance.py", line 274, in _run_raw_task
    TaskInstance._execute_task_with_callbacks(
  File "/home/airflow/.local/lib/python3.12/site-packages/airflow/models/taskinstance.py", line 3161, in _execute_task_with_callbacks
    result = self._execute_task(context, task_orig)
             ^^^^^^^^^^^^^^^^^^^^^^^^^^^^^^^^^^^^^^
  File "/home/airflow/.local/lib/python3.12/site-packages/airflow/models/taskinstance.py", line 3185, in _execute_task
    return _execute_task(self, context, task_orig)
           ^^^^^^^^^^^^^^^^^^^^^^^^^^^^^^^^^^^^^^^
  File "/home/airflow/.local/lib/python3.12/site-packages/airflow/models/taskinstance.py", line 768, in _execute_task
    result = _execute_callable(context=context, **execute_callable_kwargs)
             ^^^^^^^^^^^^^^^^^^^^^^^^^^^^^^^^^^^^^^^^^^^^^^^^^^^^^^^^^^^^^
  File "/home/airflow/.local/lib/python3.12/site-packages/airflow/models/taskinstance.py", line 734, in _execute_callable
    return ExecutionCallableRunner(
           ^^^^^^^^^^^^^^^^^^^^^^^^
  File "/home/airflow/.local/lib/python3.12/site-packages/airflow/utils/operator_helpers.py", line 252, in run
    return self.func(*args, **kwargs)
           ^^^^^^^^^^^^^^^^^^^^^^^^^^
  File "/home/airflow/.local/lib/python3.12/site-packages/airflow/models/baseoperator.py", line 424, in wrapper
    return func(self, *args, **kwargs)
           ^^^^^^^^^^^^^^^^^^^^^^^^^^^
  File "/home/airflow/.local/lib/python3.12/site-packages/airflow/operators/python.py", line 238, in execute
    return_value = self.execute_callable()
                   ^^^^^^^^^^^^^^^^^^^^^^^
  File "/home/airflow/.local/lib/python3.12/site-packages/airflow/operators/python.py", line 256, in execute_callable
    return runner.run(*self.op_args, **self.op_kwargs)
           ^^^^^^^^^^^^^^^^^^^^^^^^^^^^^^^^^^^^^^^^^^^
  File "/home/airflow/.local/lib/python3.12/site-packages/airflow/utils/operator_helpers.py", line 252, in run
    return self.func(*args, **kwargs)
           ^^^^^^^^^^^^^^^^^^^^^^^^^^
  File "/opt/airflow/dags/dag1.py", line 51, in get_and_parse_articles
    articles = parse_google_news(html)
               ^^^^^^^^^^^^^^^^^^^^^^^
  File "/opt/airflow/dags/google_news_scraper.py", line 213, in parse_google_news
    article_counter = get_next_article_id()  # Initialize counter from the last ID in the DB
                      ^^^^^^^^^^^^^^^^^^^^^
  File "/opt/airflow/dags/google_news_scraper.py", line 172, in get_next_article_id
    last_article = collection.find_one(sort=[("article_id", -1)])
                   ^^^^^^^^^^^^^^^^^^^^^^^^^^^^^^^^^^^^^^^^^^^^^^
  File "/home/airflow/.local/lib/python3.12/site-packages/pymongo/synchronous/collection.py", line 1755, in find_one
    for result in cursor.limit(-1):
                  ^^^^^^^^^^^^^^^^
  File "/home/airflow/.local/lib/python3.12/site-packages/pymongo/synchronous/cursor.py", line 1281, in __next__
    return self.next()
           ^^^^^^^^^^^
  File "/home/airflow/.local/lib/python3.12/site-packages/pymongo/synchronous/cursor.py", line 1257, in next
    if len(self._data) or self._refresh():
                          ^^^^^^^^^^^^^^^
  File "/home/airflow/.local/lib/python3.12/site-packages/pymongo/synchronous/cursor.py", line 1205, in _refresh
    self._send_message(q)
  File "/home/airflow/.local/lib/python3.12/site-packages/pymongo/synchronous/cursor.py", line 1100, in _send_message
    response = client._run_operation(
               ^^^^^^^^^^^^^^^^^^^^^^
  File "/home/airflow/.local/lib/python3.12/site-packages/pymongo/_csot.py", line 119, in csot_wrapper
    return func(self, *args, **kwargs)
           ^^^^^^^^^^^^^^^^^^^^^^^^^^^
  File "/home/airflow/.local/lib/python3.12/site-packages/pymongo/synchronous/mongo_client.py", line 1752, in _run_operation
    return self._retryable_read(
           ^^^^^^^^^^^^^^^^^^^^^
  File "/home/airflow/.local/lib/python3.12/site-packages/pymongo/synchronous/mongo_client.py", line 1861, in _retryable_read
    return self._retry_internal(
           ^^^^^^^^^^^^^^^^^^^^^
  File "/home/airflow/.local/lib/python3.12/site-packages/pymongo/_csot.py", line 119, in csot_wrapper
    return func(self, *args, **kwargs)
           ^^^^^^^^^^^^^^^^^^^^^^^^^^^
  File "/home/airflow/.local/lib/python3.12/site-packages/pymongo/synchronous/mongo_client.py", line 1828, in _retry_internal
    ).run()
      ^^^^^
  File "/home/airflow/.local/lib/python3.12/site-packages/pymongo/synchronous/mongo_client.py", line 2565, in run
    return self._read() if self._is_read else self._write()
           ^^^^^^^^^^^^
  File "/home/airflow/.local/lib/python3.12/site-packages/pymongo/synchronous/mongo_client.py", line 2700, in _read
    self._server = self._get_server()
                   ^^^^^^^^^^^^^^^^^^
  File "/home/airflow/.local/lib/python3.12/site-packages/pymongo/synchronous/mongo_client.py", line 2656, in _get_server
    return self._client._select_server(
           ^^^^^^^^^^^^^^^^^^^^^^^^^^^^
  File "/home/airflow/.local/lib/python3.12/site-packages/pymongo/synchronous/mongo_client.py", line 1647, in _select_server
    server = topology.select_server(
             ^^^^^^^^^^^^^^^^^^^^^^^
  File "/home/airflow/.local/lib/python3.12/site-packages/pymongo/synchronous/topology.py", line 402, in select_server
    server = self._select_server(
             ^^^^^^^^^^^^^^^^^^^^
  File "/home/airflow/.local/lib/python3.12/site-packages/pymongo/synchronous/topology.py", line 380, in _select_server
    servers = self.select_servers(
              ^^^^^^^^^^^^^^^^^^^^
  File "/home/airflow/.local/lib/python3.12/site-packages/pymongo/synchronous/topology.py", line 287, in select_servers
    server_descriptions = self._select_servers_loop(
                          ^^^^^^^^^^^^^^^^^^^^^^^^^^
  File "/home/airflow/.local/lib/python3.12/site-packages/pymongo/synchronous/topology.py", line 337, in _select_servers_loop
    raise ServerSelectionTimeoutError(
pymongo.errors.ServerSelectionTimeoutError: localhost:27017: [Errno 111] Connection refused (configured timeouts: socketTimeoutMS: 20000.0ms, connectTimeoutMS: 20000.0ms), Timeout: 30s, Topology Description: <TopologyDescription id: 67b1c2a3feba17ec89b72109, topology_type: Unknown, servers: [<ServerDescription ('localhost', 27017) server_type: Unknown, rtt: None, error=AutoReconnect('localhost:27017: [Errno 111] Connection refused (configured timeouts: socketTimeoutMS: 20000.0ms, connectTimeoutMS: 20000.0ms)')>]>
[2025-02-16T10:49:41.200+0000] {local_task_job_runner.py:266} INFO - Task exited with return code 1
[2025-02-16T10:49:41.220+0000] {taskinstance.py:3901} INFO - 0 downstream tasks scheduled from follow-on schedule check
[2025-02-16T10:49:41.223+0000] {local_task_job_runner.py:245} INFO - ::endgroup::
